Workbook

Sheet ALEJANDRO TORRES LUNA
B2: SUPERVISOR
B3: ALEJANDRO TORRES LUNA
B5: PERIODO | C5: JUNIO | D5: AÑO 2026
B6: ASESORES
B7: No. EMP | C7: NOMBRE | D7: VERDE | E7: AMARILLO | F7: ROJO | G7: ROJO FUERTE | H7: FALTA | I7: VACACIONES | J7: FESTIVO | K7: INCAPACIDAD | L7: PERMISO | M7: DESCANSO | N7: DESCANSO POR DINAMICA | O7: DINAMICA
B8: {=IFERROR(INDEX(PERSONAL!$A:$A,MATCH($B$3&"|"&1,PERSONAL!$N:$N,0)),"")} | C8: {=IFERROR(INDEX(PERSONAL!$B:$B,MATCH($B$3&"|"&1,PERSONAL!$N:$N,0)),"")} | D8: =IF($B8="","",COUNTIFS(REGISTRO!$B$2:$B$1722,$B8,REGISTRO!$H$2:$H$1722,$C$5,REGISTRO!$J$2:$J$1722,"VERDE")) | E8: =IF($B8="","",COUNTIFS(REGISTRO!$B$2:$B$1722,$B8,REGISTRO!$H$2:$H$1722,$C$5,REGISTRO!$J$2:$J$1722,"AMARILLO")) | F8: =IF($B8="","",COUNTIFS(REGISTRO!$B$2:$B$1722,$B8,REGISTRO!$H$2:$H$1722,$C$5,REGISTRO!$J$2:$J$1722,"ROJO")) | G8: =IF($B8="","",COUNTIFS(REGISTRO!$B$2:$B$1722,$B8,REGISTRO!$H$2:$H$1722,$C$5,REGISTRO!$J$2:$J$1722,"ROJO FUERTE")) | H8: =IF($B8="","",COUNTIFS(REGISTRO!$B$2:$B$1722,$B8,REGISTRO!$H$2:$H$1722,$C$5,REGISTRO!$J$2:$J$1722,"FALTA")) | I8: =IF($B8="","",COUNTIFS(REGISTRO!$B$2:$B$1722,$B8,REGISTRO!$H$2:$H$1722,$C$5,REGISTRO!$J$2:$J$1722,"VACACIONES")) | J8: =IF($B8="","",COUNTIFS(REGISTRO!$B$2:$B$1722,$B8,REGISTRO!$H$2:$H$1722,$C$5,REGISTRO!$J$2:$J$1722,"FESTIVO")) | K8: =IF($B8="","",COUNTIFS(REGISTRO!$B$2:$B$1722,$B8,REGISTRO!$H$2:$H$1722,$C$5,REGISTRO!$J$2:$J$1722,"INCAPACIDAD")) | L8: =IF($B8="","",COUNTIFS(REGISTRO!$B$2:$B$1722,$B8,REGISTRO!$H$2:$H$1722,$C$5,REGISTRO!$J$2:$J$1722,"PERMISO")) | M8: =IF($B8="","",COUNTIFS(REGISTRO!$B$2:$B$1722,$B8,REGISTRO!$H$2:$H$1722,$C$5,REGISTRO!$J$2:$J$1722,"DESCANSO")) | N8: =IF($B8="","",COUNTIFS(REGISTRO!$B$2:$B$1722,$B8,REGISTRO!$H$2:$H$1722,$C$5,REGISTRO!$J$2:$J$1722,"DESCANSO POR DINAMICA")) | O8: =IF($B8="","",COUNTIFS(REGISTRO!$B$2:$B$1722,$B8,REGISTRO!$H$2:$H$1722,$C$5,REGISTRO!$J$2:$J$1722,"DINAMICA"))
B9: {=IFERROR(INDEX(PERSONAL!$A:$A,MATCH($B$3&"|"&2,PERSONAL!$N:$N,0)),"")} | C9: {=IFERROR(INDEX(PERSONAL!$B:$B,MATCH($B$3&"|"&2,PERSONAL!$N:$N,0)),"")} | D9: =IF($B9="","",COUNTIFS(REGISTRO!$B$2:$B$1722,$B9,REGISTRO!$H$2:$H$1722,$C$5,REGISTRO!$J$2:$J$1722,"VERDE")) | E9: =IF($B9="","",COUNTIFS(REGISTRO!$B$2:$B$1722,$B9,REGISTRO!$H$2:$H$1722,$C$5,REGISTRO!$J$2:$J$1722,"AMARILLO")) | F9: =IF($B9="","",COUNTIFS(REGISTRO!$B$2:$B$1722,$B9,REGISTRO!$H$2:$H$1722,$C$5,REGISTRO!$J$2:$J$1722,"ROJO")) | G9: =IF($B9="","",COUNTIFS(REGISTRO!$B$2:$B$1722,$B9,REGISTRO!$H$2:$H$1722,$C$5,REGISTRO!$J$2:$J$1722,"ROJO FUERTE")) | H9: =IF($B9="","",COUNTIFS(REGISTRO!$B$2:$B$1722,$B9,REGISTRO!$H$2:$H$1722,$C$5,REGISTRO!$J$2:$J$1722,"FALTA")) | I9: =IF($B9="","",COUNTIFS(REGISTRO!$B$2:$B$1722,$B9,REGISTRO!$H$2:$H$1722,$C$5,REGISTRO!$J$2:$J$1722,"VACACIONES")) | J9: =IF($B9="","",COUNTIFS(REGISTRO!$B$2:$B$1722,$B9,REGISTRO!$H$2:$H$1722,$C$5,REGISTRO!$J$2:$J$1722,"FESTIVO")) | K9: =IF($B9="","",COUNTIFS(REGISTRO!$B$2:$B$1722,$B9,REGISTRO!$H$2:$H$1722,$C$5,REGISTRO!$J$2:$J$1722,"INCAPACIDAD")) | L9: =IF($B9="","",COUNTIFS(REGISTRO!$B$2:$B$1722,$B9,REGISTRO!$H$2:$H$1722,$C$5,REGISTRO!$J$2:$J$1722,"PERMISO")) | M9: =IF($B9="","",COUNTIFS(REGISTRO!$B$2:$B$1722,$B9,REGISTRO!$H$2:$H$1722,$C$5,REGISTRO!$J$2:$J$1722,"DESCANSO")) | N9: =IF($B9="","",COUNTIFS(REGISTRO!$B$2:$B$1722,$B9,REGISTRO!$H$2:$H$1722,$C$5,REGISTRO!$J$2:$J$1722,"DESCANSO POR DINAMICA")) | O9: =IF($B9="","",COUNTIFS(REGISTRO!$B$2:$B$1722,$B9,REGISTRO!$H$2:$H$1722,$C$5,REGISTRO!$J$2:$J$1722,"DINAMICA"))
B10: {=IFERROR(INDEX(PERSONAL!$A:$A,MATCH($B$3&"|"&3,PERSONAL!$N:$N,0)),"")} | C10: {=IFERROR(INDEX(PERSONAL!$B:$B,MATCH($B$3&"|"&3,PERSONAL!$N:$N,0)),"")} | D10: =IF($B10="","",COUNTIFS(REGISTRO!$B$2:$B$1722,$B10,REGISTRO!$H$2:$H$1722,$C$5,REGISTRO!$J$2:$J$1722,"VERDE")) | E10: =IF($B10="","",COUNTIFS(REGISTRO!$B$2:$B$1722,$B10,REGISTRO!$H$2:$H$1722,$C$5,REGISTRO!$J$2:$J$1722,"AMARILLO")) | F10: =IF($B10="","",COUNTIFS(REGISTRO!$B$2:$B$1722,$B10,REGISTRO!$H$2:$H$1722,$C$5,REGISTRO!$J$2:$J$1722,"ROJO")) | G10: =IF($B10="","",COUNTIFS(REGISTRO!$B$2:$B$1722,$B10,REGISTRO!$H$2:$H$1722,$C$5,REGISTRO!$J$2:$J$1722,"ROJO FUERTE")) | H10: =IF($B10="","",COUNTIFS(REGISTRO!$B$2:$B$1722,$B10,REGISTRO!$H$2:$H$1722,$C$5,REGISTRO!$J$2:$J$1722,"FALTA")) | I10: =IF($B10="","",COUNTIFS(REGISTRO!$B$2:$B$1722,$B10,REGISTRO!$H$2:$H$1722,$C$5,REGISTRO!$J$2:$J$1722,"VACACIONES")) | J10: =IF($B10="","",COUNTIFS(REGISTRO!$B$2:$B$1722,$B10,REGISTRO!$H$2:$H$1722,$C$5,REGISTRO!$J$2:$J$1722,"FESTIVO")) | K10: =IF($B10="","",COUNTIFS(REGISTRO!$B$2:$B$1722,$B10,REGISTRO!$H$2:$H$1722,$C$5,REGISTRO!$J$2:$J$1722,"INCAPACIDAD")) | L10: =IF($B10="","",COUNTIFS(REGISTRO!$B$2:$B$1722,$B10,REGISTRO!$H$2:$H$1722,$C$5,REGISTRO!$J$2:$J$1722,"PERMISO")) | M10: =IF($B10="","",COUNTIFS(REGISTRO!$B$2:$B$1722,$B10,REGISTRO!$H$2:$H$1722,$C$5,REGISTRO!$J$2:$J$1722,"DESCANSO")) | N10: =IF($B10="","",COUNTIFS(REGISTRO!$B$2:$B$1722,$B10,REGISTRO!$H$2:$H$1722,$C$5,REGISTRO!$J$2:$J$1722,"DESCANSO POR DINAMICA")) | O10: =IF($B10="","",COUNTIFS(REGISTRO!$B$2:$B$1722,$B10,REGISTRO!$H$2:$H$1722,$C$5,REGISTRO!$J$2:$J$1722,"DINAMICA"))
B11: {=IFERROR(INDEX(PERSONAL!$A:$A,MATCH($B$3&"|"&4,PERSONAL!$N:$N,0)),"")} | C11: {=IFERROR(INDEX(PERSONAL!$B:$B,MATCH($B$3&"|"&4,PERSONAL!$N:$N,0)),"")} | D11: =IF($B11="","",COUNTIFS(REGISTRO!$B$2:$B$1722,$B11,REGISTRO!$H$2:$H$1722,$C$5,REGISTRO!$J$2:$J$1722,"VERDE")) | E11: =IF($B11="","",COUNTIFS(REGISTRO!$B$2:$B$1722,$B11,REGISTRO!$H$2:$H$1722,$C$5,REGISTRO!$J$2:$J$1722,"AMARILLO")) | F11: =IF($B11="","",COUNTIFS(REGISTRO!$B$2:$B$1722,$B11,REGISTRO!$H$2:$H$1722,$C$5,REGISTRO!$J$2:$J$1722,"ROJO")) | G11: =IF($B11="","",COUNTIFS(REGISTRO!$B$2:$B$1722,$B11,REGISTRO!$H$2:$H$1722,$C$5,REGISTRO!$J$2:$J$1722,"ROJO FUERTE")) | H11: =IF($B11="","",COUNTIFS(REGISTRO!$B$2:$B$1722,$B11,REGISTRO!$H$2:$H$1722,$C$5,REGISTRO!$J$2:$J$1722,"FALTA")) | I11: =IF($B11="","",COUNTIFS(REGISTRO!$B$2:$B$1722,$B11,REGISTRO!$H$2:$H$1722,$C$5,REGISTRO!$J$2:$J$1722,"VACACIONES")) | J11: =IF($B11="","",COUNTIFS(REGISTRO!$B$2:$B$1722,$B11,REGISTRO!$H$2:$H$1722,$C$5,REGISTRO!$J$2:$J$1722,"FESTIVO")) | K11: =IF($B11="","",COUNTIFS(REGISTRO!$B$2:$B$1722,$B11,REGISTRO!$H$2:$H$1722,$C$5,REGISTRO!$J$2:$J$1722,"INCAPACIDAD")) | L11: =IF($B11="","",COUNTIFS(REGISTRO!$B$2:$B$1722,$B11,REGISTRO!$H$2:$H$1722,$C$5,REGISTRO!$J$2:$J$1722,"PERMISO")) | M11: =IF($B11="","",COUNTIFS(REGISTRO!$B$2:$B$1722,$B11,REGISTRO!$H$2:$H$1722,$C$5,REGISTRO!$J$2:$J$1722,"DESCANSO")) | N11: =IF($B11="","",COUNTIFS(REGISTRO!$B$2:$B$1722,$B11,REGISTRO!$H$2:$H$1722,$C$5,REGISTRO!$J$2:$J$1722,"DESCANSO POR DINAMICA")) | O11: =IF($B11="","",COUNTIFS(REGISTRO!$B$2:$B$1722,$B11,REGISTRO!$H$2:$H$1722,$C$5,REGISTRO!$J$2:$J$1722,"DINAMICA"))
B12: {=IFERROR(INDEX(PERSONAL!$A:$A,MATCH($B$3&"|"&5,PERSONAL!$N:$N,0)),"")} | C12: {=IFERROR(INDEX(PERSONAL!$B:$B,MATCH($B$3&"|"&5,PERSONAL!$N:$N,0)),"")} | D12: =IF($B12="","",COUNTIFS(REGISTRO!$B$2:$B$1722,$B12,REGISTRO!$H$2:$H$1722,$C$5,REGISTRO!$J$2:$J$1722,"VERDE")) | E12: =IF($B12="","",COUNTIFS(REGISTRO!$B$2:$B$1722,$B12,REGISTRO!$H$2:$H$1722,$C$5,REGISTRO!$J$2:$J$1722,"AMARILLO")) | F12: =IF($B12="","",COUNTIFS(REGISTRO!$B$2:$B$1722,$B12,REGISTRO!$H$2:$H$1722,$C$5,REGISTRO!$J$2:$J$1722,"ROJO")) | G12: =IF($B12="","",COUNTIFS(REGISTRO!$B$2:$B$1722,$B12,REGISTRO!$H$2:$H$1722,$C$5,REGISTRO!$J$2:$J$1722,"ROJO FUERTE")) | H12: =IF($B12="","",COUNTIFS(REGISTRO!$B$2:$B$1722,$B12,REGISTRO!$H$2:$H$1722,$C$5,REGISTRO!$J$2:$J$1722,"FALTA")) | I12: =IF($B12="","",COUNTIFS(REGISTRO!$B$2:$B$1722,$B12,REGISTRO!$H$2:$H$1722,$C$5,REGISTRO!$J$2:$J$1722,"VACACIONES")) | J12: =IF($B12="","",COUNTIFS(REGISTRO!$B$2:$B$1722,$B12,REGISTRO!$H$2:$H$1722,$C$5,REGISTRO!$J$2:$J$1722,"FESTIVO")) | K12: =IF($B12="","",COUNTIFS(REGISTRO!$B$2:$B$1722,$B12,REGISTRO!$H$2:$H$1722,$C$5,REGISTRO!$J$2:$J$1722,"INCAPACIDAD")) | L12: =IF($B12="","",COUNTIFS(REGISTRO!$B$2:$B$1722,$B12,REGISTRO!$H$2:$H$1722,$C$5,REGISTRO!$J$2:$J$1722,"PERMISO")) | M12: =IF($B12="","",COUNTIFS(REGISTRO!$B$2:$B$1722,$B12,REGISTRO!$H$2:$H$1722,$C$5,REGISTRO!$J$2:$J$1722,"DESCANSO")) | N12: =IF($B12="","",COUNTIFS(REGISTRO!$B$2:$B$1722,$B12,REGISTRO!$H$2:$H$1722,$C$5,REGISTRO!$J$2:$J$1722,"DESCANSO POR DINAMICA")) | O12: =IF($B12="","",COUNTIFS(REGISTRO!$B$2:$B$1722,$B12,REGISTRO!$H$2:$H$1722,$C$5,REGISTRO!$J$2:$J$1722,"DINAMICA"))
B13: {=IFERROR(INDEX(PERSONAL!$A:$A,MATCH($B$3&"|"&6,PERSONAL!$N:$N,0)),"")} | C13: {=IFERROR(INDEX(PERSONAL!$B:$B,MATCH($B$3&"|"&6,PERSONAL!$N:$N,0)),"")} | D13: =IF($B13="","",COUNTIFS(REGISTRO!$B$2:$B$1722,$B13,REGISTRO!$H$2:$H$1722,$C$5,REGISTRO!$J$2:$J$1722,"VERDE")) | E13: =IF($B13="","",COUNTIFS(REGISTRO!$B$2:$B$1722,$B13,REGISTRO!$H$2:$H$1722,$C$5,REGISTRO!$J$2:$J$1722,"AMARILLO")) | F13: =IF($B13="","",COUNTIFS(REGISTRO!$B$2:$B$1722,$B13,REGISTRO!$H$2:$H$1722,$C$5,REGISTRO!$J$2:$J$1722,"ROJO")) | G13: =IF($B13="","",COUNTIFS(REGISTRO!$B$2:$B$1722,$B13,REGISTRO!$H$2:$H$1722,$C$5,REGISTRO!$J$2:$J$1722,"ROJO FUERTE")) | H13: =IF($B13="","",COUNTIFS(REGISTRO!$B$2:$B$1722,$B13,REGISTRO!$H$2:$H$1722,$C$5,REGISTRO!$J$2:$J$1722,"FALTA")) | I13: =IF($B13="","",COUNTIFS(REGISTRO!$B$2:$B$1722,$B13,REGISTRO!$H$2:$H$1722,$C$5,REGISTRO!$J$2:$J$1722,"VACACIONES")) | J13: =IF($B13="","",COUNTIFS(REGISTRO!$B$2:$B$1722,$B13,REGISTRO!$H$2:$H$1722,$C$5,REGISTRO!$J$2:$J$1722,"FESTIVO")) | K13: =IF($B13="","",COUNTIFS(REGISTRO!$B$2:$B$1722,$B13,REGISTRO!$H$2:$H$1722,$C$5,REGISTRO!$J$2:$J$1722,"INCAPACIDAD")) | L13: =IF($B13="","",COUNTIFS(REGISTRO!$B$2:$B$1722,$B13,REGISTRO!$H$2:$H$1722,$C$5,REGISTRO!$J$2:$J$1722,"PERMISO")) | M13: =IF($B13="","",COUNTIFS(REGISTRO!$B$2:$B$1722,$B13,REGISTRO!$H$2:$H$1722,$C$5,REGISTRO!$J$2:$J$1722,"DESCANSO")) | N13: =IF($B13="","",COUNTIFS(REGISTRO!$B$2:$B$1722,$B13,REGISTRO!$H$2:$H$1722,$C$5,REGISTRO!$J$2:$J$1722,"DESCANSO POR DINAMICA")) | O13: =IF($B13="","",COUNTIFS(REGISTRO!$B$2:$B$1722,$B13,REGISTRO!$H$2:$H$1722,$C$5,REGISTRO!$J$2:$J$1722,"DINAMICA"))
B14: {=IFERROR(INDEX(PERSONAL!$A:$A,MATCH($B$3&"|"&7,PERSONAL!$N:$N,0)),"")} | C14: {=IFERROR(INDEX(PERSONAL!$B:$B,MATCH($B$3&"|"&7,PERSONAL!$N:$N,0)),"")} | D14: =IF($B14="","",COUNTIFS(REGISTRO!$B$2:$B$1722,$B14,REGISTRO!$H$2:$H$1722,$C$5,REGISTRO!$J$2:$J$1722,"VERDE")) | E14: =IF($B14="","",COUNTIFS(REGISTRO!$B$2:$B$1722,$B14,REGISTRO!$H$2:$H$1722,$C$5,REGISTRO!$J$2:$J$1722,"AMARILLO")) | F14: =IF($B14="","",COUNTIFS(REGISTRO!$B$2:$B$1722,$B14,REGISTRO!$H$2:$H$1722,$C$5,REGISTRO!$J$2:$J$1722,"ROJO")) | G14: =IF($B14="","",COUNTIFS(REGISTRO!$B$2:$B$1722,$B14,REGISTRO!$H$2:$H$1722,$C$5,REGISTRO!$J$2:$J$1722,"ROJO FUERTE")) | H14: =IF($B14="","",COUNTIFS(REGISTRO!$B$2:$B$1722,$B14,REGISTRO!$H$2:$H$1722,$C$5,REGISTRO!$J$2:$J$1722,"FALTA")) | I14: =IF($B14="","",COUNTIFS(REGISTRO!$B$2:$B$1722,$B14,REGISTRO!$H$2:$H$1722,$C$5,REGISTRO!$J$2:$J$1722,"VACACIONES")) | J14: =IF($B14="","",COUNTIFS(REGISTRO!$B$2:$B$1722,$B14,REGISTRO!$H$2:$H$1722,$C$5,REGISTRO!$J$2:$J$1722,"FESTIVO")) | K14: =IF($B14="","",COUNTIFS(REGISTRO!$B$2:$B$1722,$B14,REGISTRO!$H$2:$H$1722,$C$5,REGISTRO!$J$2:$J$1722,"INCAPACIDAD")) | L14: =IF($B14="","",COUNTIFS(REGISTRO!$B$2:$B$1722,$B14,REGISTRO!$H$2:$H$1722,$C$5,REGISTRO!$J$2:$J$1722,"PERMISO")) | M14: =IF($B14="","",COUNTIFS(REGISTRO!$B$2:$B$1722,$B14,REGISTRO!$H$2:$H$1722,$C$5,REGISTRO!$J$2:$J$1722,"DESCANSO")) | N14: =IF($B14="","",COUNTIFS(REGISTRO!$B$2:$B$1722,$B14,REGISTRO!$H$2:$H$1722,$C$5,REGISTRO!$J$2:$J$1722,"DESCANSO POR DINAMICA")) | O14: =IF($B14="","",COUNTIFS(REGISTRO!$B$2:$B$1722,$B14,REGISTRO!$H$2:$H$1722,$C$5,REGISTRO!$J$2:$J$1722,"DINAMICA"))
B15: {=IFERROR(INDEX(PERSONAL!$A:$A,MATCH($B$3&"|"&8,PERSONAL!$N:$N,0)),"")} | C15: {=IFERROR(INDEX(PERSONAL!$B:$B,MATCH($B$3&"|"&8,PERSONAL!$N:$N,0)),"")} | D15: =IF($B15="","",COUNTIFS(REGISTRO!$B$2:$B$1722,$B15,REGISTRO!$H$2:$H$1722,$C$5,REGISTRO!$J$2:$J$1722,"VERDE")) | E15: =IF($B15="","",COUNTIFS(REGISTRO!$B$2:$B$1722,$B15,REGISTRO!$H$2:$H$1722,$C$5,REGISTRO!$J$2:$J$1722,"AMARILLO")) | F15: =IF($B15="","",COUNTIFS(REGISTRO!$B$2:$B$1722,$B15,REGISTRO!$H$2:$H$1722,$C$5,REGISTRO!$J$2:$J$1722,"ROJO")) | G15: =IF($B15="","",COUNTIFS(REGISTRO!$B$2:$B$1722,$B15,REGISTRO!$H$2:$H$1722,$C$5,REGISTRO!$J$2:$J$1722,"ROJO FUERTE")) | H15: =IF($B15="","",COUNTIFS(REGISTRO!$B$2:$B$1722,$B15,REGISTRO!$H$2:$H$1722,$C$5,REGISTRO!$J$2:$J$1722,"FALTA")) | I15: =IF($B15="","",COUNTIFS(REGISTRO!$B$2:$B$1722,$B15,REGISTRO!$H$2:$H$1722,$C$5,REGISTRO!$J$2:$J$1722,"VACACIONES")) | J15: =IF($B15="","",COUNTIFS(REGISTRO!$B$2:$B$1722,$B15,REGISTRO!$H$2:$H$1722,$C$5,REGISTRO!$J$2:$J$1722,"FESTIVO")) | K15: =IF($B15="","",COUNTIFS(REGISTRO!$B$2:$B$1722,$B15,REGISTRO!$H$2:$H$1722,$C$5,REGISTRO!$J$2:$J$1722,"INCAPACIDAD")) | L15: =IF($B15="","",COUNTIFS(REGISTRO!$B$2:$B$1722,$B15,REGISTRO!$H$2:$H$1722,$C$5,REGISTRO!$J$2:$J$1722,"PERMISO")) | M15: =IF($B15="","",COUNTIFS(REGISTRO!$B$2:$B$1722,$B15,REGISTRO!$H$2:$H$1722,$C$5,REGISTRO!$J$2:$J$1722,"DESCANSO")) | N15: =IF($B15="","",COUNTIFS(REGISTRO!$B$2:$B$1722,$B15,REGISTRO!$H$2:$H$1722,$C$5,REGISTRO!$J$2:$J$1722,"DESCANSO POR DINAMICA")) | O15: =IF($B15="","",COUNTIFS(REGISTRO!$B$2:$B$1722,$B15,REGISTRO!$H$2:$H$1722,$C$5,REGISTRO!$J$2:$J$1722,"DINAMICA"))
B16: {=IFERROR(INDEX(PERSONAL!$A:$A,MATCH($B$3&"|"&9,PERSONAL!$N:$N,0)),"")} | C16: {=IFERROR(INDEX(PERSONAL!$B:$B,MATCH($B$3&"|"&9,PERSONAL!$N:$N,0)),"")} | D16: =IF($B16="","",COUNTIFS(REGISTRO!$B$2:$B$1722,$B16,REGISTRO!$H$2:$H$1722,$C$5,REGISTRO!$J$2:$J$1722,"VERDE")) | E16: =IF($B16="","",COUNTIFS(REGISTRO!$B$2:$B$1722,$B16,REGISTRO!$H$2:$H$1722,$C$5,REGISTRO!$J$2:$J$1722,"AMARILLO")) | F16: =IF($B16="","",COUNTIFS(REGISTRO!$B$2:$B$1722,$B16,REGISTRO!$H$2:$H$1722,$C$5,REGISTRO!$J$2:$J$1722,"ROJO")) | G16: =IF($B16="","",COUNTIFS(REGISTRO!$B$2:$B$1722,$B16,REGISTRO!$H$2:$H$1722,$C$5,REGISTRO!$J$2:$J$1722,"ROJO FUERTE")) | H16: =IF($B16="","",COUNTIFS(REGISTRO!$B$2:$B$1722,$B16,REGISTRO!$H$2:$H$1722,$C$5,REGISTRO!$J$2:$J$1722,"FALTA")) | I16: =IF($B16="","",COUNTIFS(REGISTRO!$B$2:$B$1722,$B16,REGISTRO!$H$2:$H$1722,$C$5,REGISTRO!$J$2:$J$1722,"VACACIONES")) | J16: =IF($B16="","",COUNTIFS(REGISTRO!$B$2:$B$1722,$B16,REGISTRO!$H$2:$H$1722,$C$5,REGISTRO!$J$2:$J$1722,"FESTIVO")) | K16: =IF($B16="","",COUNTIFS(REGISTRO!$B$2:$B$1722,$B16,REGISTRO!$H$2:$H$1722,$C$5,REGISTRO!$J$2:$J$1722,"INCAPACIDAD")) | L16: =IF($B16="","",COUNTIFS(REGISTRO!$B$2:$B$1722,$B16,REGISTRO!$H$2:$H$1722,$C$5,REGISTRO!$J$2:$J$1722,"PERMISO")) | M16: =IF($B16="","",COUNTIFS(REGISTRO!$B$2:$B$1722,$B16,REGISTRO!$H$2:$H$1722,$C$5,REGISTRO!$J$2:$J$1722,"DESCANSO")) | N16: =IF($B16="","",COUNTIFS(REGISTRO!$B$2:$B$1722,$B16,REGISTRO!$H$2:$H$1722,$C$5,REGISTRO!$J$2:$J$1722,"DESCANSO POR DINAMICA")) | O16: =IF($B16="","",COUNTIFS(REGISTRO!$B$2:$B$1722,$B16,REGISTRO!$H$2:$H$1722,$C$5,REGISTRO!$J$2:$J$1722,"DINAMICA"))
B17: {=IFERROR(INDEX(PERSONAL!$A:$A,MATCH($B$3&"|"&10,PERSONAL!$N:$N,0)),"")} | C17: {=IFERROR(INDEX(PERSONAL!$B:$B,MATCH($B$3&"|"&10,PERSONAL!$N:$N,0)),"")} | D17: =IF($B17="","",COUNTIFS(REGISTRO!$B$2:$B$1722,$B17,REGISTRO!$H$2:$H$1722,$C$5,REGISTRO!$J$2:$J$1722,"VERDE")) | E17: =IF($B17="","",COUNTIFS(REGISTRO!$B$2:$B$1722,$B17,REGISTRO!$H$2:$H$1722,$C$5,REGISTRO!$J$2:$J$1722,"AMARILLO")) | F17: =IF($B17="","",COUNTIFS(REGISTRO!$B$2:$B$1722,$B17,REGISTRO!$H$2:$H$1722,$C$5,REGISTRO!$J$2:$J$1722,"ROJO")) | G17: =IF($B17="","",COUNTIFS(REGISTRO!$B$2:$B$1722,$B17,REGISTRO!$H$2:$H$1722,$C$5,REGISTRO!$J$2:$J$1722,"ROJO FUERTE")) | H17: =IF($B17="","",COUNTIFS(REGISTRO!$B$2:$B$1722,$B17,REGISTRO!$H$2:$H$1722,$C$5,REGISTRO!$J$2:$J$1722,"FALTA")) | I17: =IF($B17="","",COUNTIFS(REGISTRO!$B$2:$B$1722,$B17,REGISTRO!$H$2:$H$1722,$C$5,REGISTRO!$J$2:$J$1722,"VACACIONES")) | J17: =IF($B17="","",COUNTIFS(REGISTRO!$B$2:$B$1722,$B17,REGISTRO!$H$2:$H$1722,$C$5,REGISTRO!$J$2:$J$1722,"FESTIVO")) | K17: =IF($B17="","",COUNTIFS(REGISTRO!$B$2:$B$1722,$B17,REGISTRO!$H$2:$H$1722,$C$5,REGISTRO!$J$2:$J$1722,"INCAPACIDAD")) | L17: =IF($B17="","",COUNTIFS(REGISTRO!$B$2:$B$1722,$B17,REGISTRO!$H$2:$H$1722,$C$5,REGISTRO!$J$2:$J$1722,"PERMISO")) | M17: =IF($B17="","",COUNTIFS(REGISTRO!$B$2:$B$1722,$B17,REGISTRO!$H$2:$H$1722,$C$5,REGISTRO!$J$2:$J$1722,"DESCANSO")) | N17: =IF($B17="","",COUNTIFS(REGISTRO!$B$2:$B$1722,$B17,REGISTRO!$H$2:$H$1722,$C$5,REGISTRO!$J$2:$J$1722,"DESCANSO POR DINAMICA")) | O17: =IF($B17="","",COUNTIFS(REGISTRO!$B$2:$B$1722,$B17,REGISTRO!$H$2:$H$1722,$C$5,REGISTRO!$J$2:$J$1722,"DINAMICA"))
B18: {=IFERROR(INDEX(PERSONAL!$A:$A,MATCH($B$3&"|"&11,PERSONAL!$N:$N,0)),"")} | C18: {=IFERROR(INDEX(PERSONAL!$B:$B,MATCH($B$3&"|"&11,PERSONAL!$N:$N,0)),"")} | D18: =IF($B18="","",COUNTIFS(REGISTRO!$B$2:$B$1722,$B18,REGISTRO!$H$2:$H$1722,$C$5,REGISTRO!$J$2:$J$1722,"VERDE")) | E18: =IF($B18="","",COUNTIFS(REGISTRO!$B$2:$B$1722,$B18,REGISTRO!$H$2:$H$1722,$C$5,REGISTRO!$J$2:$J$1722,"AMARILLO")) | F18: =IF($B18="","",COUNTIFS(REGISTRO!$B$2:$B$1722,$B18,REGISTRO!$H$2:$H$1722,$C$5,REGISTRO!$J$2:$J$1722,"ROJO")) | G18: =IF($B18="","",COUNTIFS(REGISTRO!$B$2:$B$1722,$B18,REGISTRO!$H$2:$H$1722,$C$5,REGISTRO!$J$2:$J$1722,"ROJO FUERTE")) | H18: =IF($B18="","",COUNTIFS(REGISTRO!$B$2:$B$1722,$B18,REGISTRO!$H$2:$H$1722,$C$5,REGISTRO!$J$2:$J$1722,"FALTA")) | I18: =IF($B18="","",COUNTIFS(REGISTRO!$B$2:$B$1722,$B18,REGISTRO!$H$2:$H$1722,$C$5,REGISTRO!$J$2:$J$1722,"VACACIONES")) | J18: =IF($B18="","",COUNTIFS(REGISTRO!$B$2:$B$1722,$B18,REGISTRO!$H$2:$H$1722,$C$5,REGISTRO!$J$2:$J$1722,"FESTIVO")) | K18: =IF($B18="","",COUNTIFS(REGISTRO!$B$2:$B$1722,$B18,REGISTRO!$H$2:$H$1722,$C$5,REGISTRO!$J$2:$J$1722,"INCAPACIDAD")) | L18: =IF($B18="","",COUNTIFS(REGISTRO!$B$2:$B$1722,$B18,REGISTRO!$H$2:$H$1722,$C$5,REGISTRO!$J$2:$J$1722,"PERMISO")) | M18: =IF($B18="","",COUNTIFS(REGISTRO!$B$2:$B$1722,$B18,REGISTRO!$H$2:$H$1722,$C$5,REGISTRO!$J$2:$J$1722,"DESCANSO")) | N18: =IF($B18="","",COUNTIFS(REGISTRO!$B$2:$B$1722,$B18,REGISTRO!$H$2:$H$1722,$C$5,REGISTRO!$J$2:$J$1722,"DESCANSO POR DINAMICA")) | O18: =IF($B18="","",COUNTIFS(REGISTRO!$B$2:$B$1722,$B18,REGISTRO!$H$2:$H$1722,$C$5,REGISTRO!$J$2:$J$1722,"DINAMICA"))
B19: {=IFERROR(INDEX(PERSONAL!$A:$A,MATCH($B$3&"|"&12,PERSONAL!$N:$N,0)),"")} | C19: {=IFERROR(INDEX(PERSONAL!$B:$B,MATCH($B$3&"|"&12,PERSONAL!$N:$N,0)),"")} | D19: =IF($B19="","",COUNTIFS(REGISTRO!$B$2:$B$1722,$B19,REGISTRO!$H$2:$H$1722,$C$5,REGISTRO!$J$2:$J$1722,"VERDE")) | E19: =IF($B19="","",COUNTIFS(REGISTRO!$B$2:$B$1722,$B19,REGISTRO!$H$2:$H$1722,$C$5,REGISTRO!$J$2:$J$1722,"AMARILLO")) | F19: =IF($B19="","",COUNTIFS(REGISTRO!$B$2:$B$1722,$B19,REGISTRO!$H$2:$H$1722,$C$5,REGISTRO!$J$2:$J$1722,"ROJO")) | G19: =IF($B19="","",COUNTIFS(REGISTRO!$B$2:$B$1722,$B19,REGISTRO!$H$2:$H$1722,$C$5,REGISTRO!$J$2:$J$1722,"ROJO FUERTE")) | H19: =IF($B19="","",COUNTIFS(REGISTRO!$B$2:$B$1722,$B19,REGISTRO!$H$2:$H$1722,$C$5,REGISTRO!$J$2:$J$1722,"FALTA")) | I19: =IF($B19="","",COUNTIFS(REGISTRO!$B$2:$B$1722,$B19,REGISTRO!$H$2:$H$1722,$C$5,REGISTRO!$J$2:$J$1722,"VACACIONES")) | J19: =IF($B19="","",COUNTIFS(REGISTRO!$B$2:$B$1722,$B19,REGISTRO!$H$2:$H$1722,$C$5,REGISTRO!$J$2:$J$1722,"FESTIVO")) | K19: =IF($B19="","",COUNTIFS(REGISTRO!$B$2:$B$1722,$B19,REGISTRO!$H$2:$H$1722,$C$5,REGISTRO!$J$2:$J$1722,"INCAPACIDAD")) | L19: =IF($B19="","",COUNTIFS(REGISTRO!$B$2:$B$1722,$B19,REGISTRO!$H$2:$H$1722,$C$5,REGISTRO!$J$2:$J$1722,"PERMISO")) | M19: =IF($B19="","",COUNTIFS(REGISTRO!$B$2:$B$1722,$B19,REGISTRO!$H$2:$H$1722,$C$5,REGISTRO!$J$2:$J$1722,"DESCANSO")) | N19: =IF($B19="","",COUNTIFS(REGISTRO!$B$2:$B$1722,$B19,REGISTRO!$H$2:$H$1722,$C$5,REGISTRO!$J$2:$J$1722,"DESCANSO POR DINAMICA")) | O19: =IF($B19="","",COUNTIFS(REGISTRO!$B$2:$B$1722,$B19,REGISTRO!$H$2:$H$1722,$C$5,REGISTRO!$J$2:$J$1722,"DINAMICA"))
B20: TOTAL | D20: =SUM(D8:D19) | E20: =SUM(E8:E19) | F20: =SUM(F8:F19) | G20: =SUM(G8:G19) | H20: =SUM(H8:H19) | I20: =SUM(I8:I19) | J20: =SUM(J8:J19) | K20: =SUM(K8:K19) | ... O20: =SUM(O8:O19)
B21: % VERDE | D21: =IF(SUM(D20:H20)=0,0,D20/SUM(D20:H20))
B22: REGISTROS / PROM. HORAS | D22: =COUNTIFS(REGISTRO!$F$2:$F$1722,$B$3,REGISTRO!$H$2:$H$1722,$C$5) | E22: =IFERROR(AVERAGEIFS(REGISTRO!$K$2:$K$1722,REGISTRO!$F$2:$F$1722,$B$3,REGISTRO!$H$2:$H$1722,$C$5),0)
A1000: Demo publico: datos ficticios anonimizados para portafolio.

Sheet CAMILA RIVERA NAVA
B2: SUPERVISOR
B3: CAMILA RIVERA NAVA
B5: PERIODO | C5: JUNIO | D5: AÑO 2026
B6: ASESORES
B7: No. EMP | C7: NOMBRE | D7: VERDE | E7: AMARILLO | F7: ROJO | G7: ROJO FUERTE | H7: FALTA | I7: VACACIONES | J7: FESTIVO | K7: INCAPACIDAD | L7: PERMISO | M7: DESCANSO | N7: DESCANSO POR DINAMICA | O7: DINAMICA
B8: {=IFERROR(INDEX(PERSONAL!$A:$A,MATCH($B$3&"|"&1,PERSONAL!$N:$N,0)),"")} | C8: {=IFERROR(INDEX(PERSONAL!$B:$B,MATCH($B$3&"|"&1,PERSONAL!$N:$N,0)),"")} | D8: =IF($B8="","",COUNTIFS(REGISTRO!$B$2:$B$1722,$B8,REGISTRO!$H$2:$H$1722,$C$5,REGISTRO!$J$2:$J$1722,"VERDE")) | E8: =IF($B8="","",COUNTIFS(REGISTRO!$B$2:$B$1722,$B8,REGISTRO!$H$2:$H$1722,$C$5,REGISTRO!$J$2:$J$1722,"AMARILLO")) | F8: =IF($B8="","",COUNTIFS(REGISTRO!$B$2:$B$1722,$B8,REGISTRO!$H$2:$H$1722,$C$5,REGISTRO!$J$2:$J$1722,"ROJO")) | G8: =IF($B8="","",COUNTIFS(REGISTRO!$B$2:$B$1722,$B8,REGISTRO!$H$2:$H$1722,$C$5,REGISTRO!$J$2:$J$1722,"ROJO FUERTE")) | H8: =IF($B8="","",COUNTIFS(REGISTRO!$B$2:$B$1722,$B8,REGISTRO!$H$2:$H$1722,$C$5,REGISTRO!$J$2:$J$1722,"FALTA")) | I8: =IF($B8="","",COUNTIFS(REGISTRO!$B$2:$B$1722,$B8,REGISTRO!$H$2:$H$1722,$C$5,REGISTRO!$J$2:$J$1722,"VACACIONES")) | J8: =IF($B8="","",COUNTIFS(REGISTRO!$B$2:$B$1722,$B8,REGISTRO!$H$2:$H$1722,$C$5,REGISTRO!$J$2:$J$1722,"FESTIVO")) | K8: =IF($B8="","",COUNTIFS(REGISTRO!$B$2:$B$1722,$B8,REGISTRO!$H$2:$H$1722,$C$5,REGISTRO!$J$2:$J$1722,"INCAPACIDAD")) | L8: =IF($B8="","",COUNTIFS(REGISTRO!$B$2:$B$1722,$B8,REGISTRO!$H$2:$H$1722,$C$5,REGISTRO!$J$2:$J$1722,"PERMISO")) | M8: =IF($B8="","",COUNTIFS(REGISTRO!$B$2:$B$1722,$B8,REGISTRO!$H$2:$H$1722,$C$5,REGISTRO!$J$2:$J$1722,"DESCANSO")) | N8: =IF($B8="","",COUNTIFS(REGISTRO!$B$2:$B$1722,$B8,REGISTRO!$H$2:$H$1722,$C$5,REGISTRO!$J$2:$J$1722,"DESCANSO POR DINAMICA")) | O8: =IF($B8="","",COUNTIFS(REGISTRO!$B$2:$B$1722,$B8,REGISTRO!$H$2:$H$1722,$C$5,REGISTRO!$J$2:$J$1722,"DINAMICA"))
B9: {=IFERROR(INDEX(PERSONAL!$A:$A,MATCH($B$3&"|"&2,PERSONAL!$N:$N,0)),"")} | C9: {=IFERROR(INDEX(PERSONAL!$B:$B,MATCH($B$3&"|"&2,PERSONAL!$N:$N,0)),"")} | D9: =IF($B9="","",COUNTIFS(REGISTRO!$B$2:$B$1722,$B9,REGISTRO!$H$2:$H$1722,$C$5,REGISTRO!$J$2:$J$1722,"VERDE")) | E9: =IF($B9="","",COUNTIFS(REGISTRO!$B$2:$B$1722,$B9,REGISTRO!$H$2:$H$1722,$C$5,REGISTRO!$J$2:$J$1722,"AMARILLO")) | F9: =IF($B9="","",COUNTIFS(REGISTRO!$B$2:$B$1722,$B9,REGISTRO!$H$2:$H$1722,$C$5,REGISTRO!$J$2:$J$1722,"ROJO")) | G9: =IF($B9="","",COUNTIFS(REGISTRO!$B$2:$B$1722,$B9,REGISTRO!$H$2:$H$1722,$C$5,REGISTRO!$J$2:$J$1722,"ROJO FUERTE")) | H9: =IF($B9="","",COUNTIFS(REGISTRO!$B$2:$B$1722,$B9,REGISTRO!$H$2:$H$1722,$C$5,REGISTRO!$J$2:$J$1722,"FALTA")) | I9: =IF($B9="","",COUNTIFS(REGISTRO!$B$2:$B$1722,$B9,REGISTRO!$H$2:$H$1722,$C$5,REGISTRO!$J$2:$J$1722,"VACACIONES")) | J9: =IF($B9="","",COUNTIFS(REGISTRO!$B$2:$B$1722,$B9,REGISTRO!$H$2:$H$1722,$C$5,REGISTRO!$J$2:$J$1722,"FESTIVO")) | K9: =IF($B9="","",COUNTIFS(REGISTRO!$B$2:$B$1722,$B9,REGISTRO!$H$2:$H$1722,$C$5,REGISTRO!$J$2:$J$1722,"INCAPACIDAD")) | L9: =IF($B9="","",COUNTIFS(REGISTRO!$B$2:$B$1722,$B9,REGISTRO!$H$2:$H$1722,$C$5,REGISTRO!$J$2:$J$1722,"PERMISO")) | M9: =IF($B9="","",COUNTIFS(REGISTRO!$B$2:$B$1722,$B9,REGISTRO!$H$2:$H$1722,$C$5,REGISTRO!$J$2:$J$1722,"DESCANSO")) | N9: =IF($B9="","",COUNTIFS(REGISTRO!$B$2:$B$1722,$B9,REGISTRO!$H$2:$H$1722,$C$5,REGISTRO!$J$2:$J$1722,"DESCANSO POR DINAMICA")) | O9: =IF($B9="","",COUNTIFS(REGISTRO!$B$2:$B$1722,$B9,REGISTRO!$H$2:$H$1722,$C$5,REGISTRO!$J$2:$J$1722,"DINAMICA"))
B10: {=IFERROR(INDEX(PERSONAL!$A:$A,MATCH($B$3&"|"&3,PERSONAL!$N:$N,0)),"")} | C10: {=IFERROR(INDEX(PERSONAL!$B:$B,MATCH($B$3&"|"&3,PERSONAL!$N:$N,0)),"")} | D10: =IF($B10="","",COUNTIFS(REGISTRO!$B$2:$B$1722,$B10,REGISTRO!$H$2:$H$1722,$C$5,REGISTRO!$J$2:$J$1722,"VERDE")) | E10: =IF($B10="","",COUNTIFS(REGISTRO!$B$2:$B$1722,$B10,REGISTRO!$H$2:$H$1722,$C$5,REGISTRO!$J$2:$J$1722,"AMARILLO")) | F10: =IF($B10="","",COUNTIFS(REGISTRO!$B$2:$B$1722,$B10,REGISTRO!$H$2:$H$1722,$C$5,REGISTRO!$J$2:$J$1722,"ROJO")) | G10: =IF($B10="","",COUNTIFS(REGISTRO!$B$2:$B$1722,$B10,REGISTRO!$H$2:$H$1722,$C$5,REGISTRO!$J$2:$J$1722,"ROJO FUERTE")) | H10: =IF($B10="","",COUNTIFS(REGISTRO!$B$2:$B$1722,$B10,REGISTRO!$H$2:$H$1722,$C$5,REGISTRO!$J$2:$J$1722,"FALTA")) | I10: =IF($B10="","",COUNTIFS(REGISTRO!$B$2:$B$1722,$B10,REGISTRO!$H$2:$H$1722,$C$5,REGISTRO!$J$2:$J$1722,"VACACIONES")) | J10: =IF($B10="","",COUNTIFS(REGISTRO!$B$2:$B$1722,$B10,REGISTRO!$H$2:$H$1722,$C$5,REGISTRO!$J$2:$J$1722,"FESTIVO")) | K10: =IF($B10="","",COUNTIFS(REGISTRO!$B$2:$B$1722,$B10,REGISTRO!$H$2:$H$1722,$C$5,REGISTRO!$J$2:$J$1722,"INCAPACIDAD")) | L10: =IF($B10="","",COUNTIFS(REGISTRO!$B$2:$B$1722,$B10,REGISTRO!$H$2:$H$1722,$C$5,REGISTRO!$J$2:$J$1722,"PERMISO")) | M10: =IF($B10="","",COUNTIFS(REGISTRO!$B$2:$B$1722,$B10,REGISTRO!$H$2:$H$1722,$C$5,REGISTRO!$J$2:$J$1722,"DESCANSO")) | N10: =IF($B10="","",COUNTIFS(REGISTRO!$B$2:$B$1722,$B10,REGISTRO!$H$2:$H$1722,$C$5,REGISTRO!$J$2:$J$1722,"DESCANSO POR DINAMICA")) | O10: =IF($B10="","",COUNTIFS(REGISTRO!$B$2:$B$1722,$B10,REGISTRO!$H$2:$H$1722,$C$5,REGISTRO!$J$2:$J$1722,"DINAMICA"))
B11: {=IFERROR(INDEX(PERSONAL!$A:$A,MATCH($B$3&"|"&4,PERSONAL!$N:$N,0)),"")} | C11: {=IFERROR(INDEX(PERSONAL!$B:$B,MATCH($B$3&"|"&4,PERSONAL!$N:$N,0)),"")} | D11: =IF($B11="","",COUNTIFS(REGISTRO!$B$2:$B$1722,$B11,REGISTRO!$H$2:$H$1722,$C$5,REGISTRO!$J$2:$J$1722,"VERDE")) | E11: =IF($B11="","",COUNTIFS(REGISTRO!$B$2:$B$1722,$B11,REGISTRO!$H$2:$H$1722,$C$5,REGISTRO!$J$2:$J$1722,"AMARILLO")) | F11: =IF($B11="","",COUNTIFS(REGISTRO!$B$2:$B$1722,$B11,REGISTRO!$H$2:$H$1722,$C$5,REGISTRO!$J$2:$J$1722,"ROJO")) | G11: =IF($B11="","",COUNTIFS(REGISTRO!$B$2:$B$1722,$B11,REGISTRO!$H$2:$H$1722,$C$5,REGISTRO!$J$2:$J$1722,"ROJO FUERTE")) | H11: =IF($B11="","",COUNTIFS(REGISTRO!$B$2:$B$1722,$B11,REGISTRO!$H$2:$H$1722,$C$5,REGISTRO!$J$2:$J$1722,"FALTA")) | I11: =IF($B11="","",COUNTIFS(REGISTRO!$B$2:$B$1722,$B11,REGISTRO!$H$2:$H$1722,$C$5,REGISTRO!$J$2:$J$1722,"VACACIONES")) | J11: =IF($B11="","",COUNTIFS(REGISTRO!$B$2:$B$1722,$B11,REGISTRO!$H$2:$H$1722,$C$5,REGISTRO!$J$2:$J$1722,"FESTIVO")) | K11: =IF($B11="","",COUNTIFS(REGISTRO!$B$2:$B$1722,$B11,REGISTRO!$H$2:$H$1722,$C$5,REGISTRO!$J$2:$J$1722,"INCAPACIDAD")) | L11: =IF($B11="","",COUNTIFS(REGISTRO!$B$2:$B$1722,$B11,REGISTRO!$H$2:$H$1722,$C$5,REGISTRO!$J$2:$J$1722,"PERMISO")) | M11: =IF($B11="","",COUNTIFS(REGISTRO!$B$2:$B$1722,$B11,REGISTRO!$H$2:$H$1722,$C$5,REGISTRO!$J$2:$J$1722,"DESCANSO")) | N11: =IF($B11="","",COUNTIFS(REGISTRO!$B$2:$B$1722,$B11,REGISTRO!$H$2:$H$1722,$C$5,REGISTRO!$J$2:$J$1722,"DESCANSO POR DINAMICA")) | O11: =IF($B11="","",COUNTIFS(REGISTRO!$B$2:$B$1722,$B11,REGISTRO!$H$2:$H$1722,$C$5,REGISTRO!$J$2:$J$1722,"DINAMICA"))
B12: {=IFERROR(INDEX(PERSONAL!$A:$A,MATCH($B$3&"|"&5,PERSONAL!$N:$N,0)),"")} | C12: {=IFERROR(INDEX(PERSONAL!$B:$B,MATCH($B$3&"|"&5,PERSONAL!$N:$N,0)),"")} | D12: =IF($B12="","",COUNTIFS(REGISTRO!$B$2:$B$1722,$B12,REGISTRO!$H$2:$H$1722,$C$5,REGISTRO!$J$2:$J$1722,"VERDE")) | E12: =IF($B12="","",COUNTIFS(REGISTRO!$B$2:$B$1722,$B12,REGISTRO!$H$2:$H$1722,$C$5,REGISTRO!$J$2:$J$1722,"AMARILLO")) | F12: =IF($B12="","",COUNTIFS(REGISTRO!$B$2:$B$1722,$B12,REGISTRO!$H$2:$H$1722,$C$5,REGISTRO!$J$2:$J$1722,"ROJO")) | G12: =IF($B12="","",COUNTIFS(REGISTRO!$B$2:$B$1722,$B12,REGISTRO!$H$2:$H$1722,$C$5,REGISTRO!$J$2:$J$1722,"ROJO FUERTE")) | H12: =IF($B12="","",COUNTIFS(REGISTRO!$B$2:$B$1722,$B12,REGISTRO!$H$2:$H$1722,$C$5,REGISTRO!$J$2:$J$1722,"FALTA")) | I12: =IF($B12="","",COUNTIFS(REGISTRO!$B$2:$B$1722,$B12,REGISTRO!$H$2:$H$1722,$C$5,REGISTRO!$J$2:$J$1722,"VACACIONES")) | J12: =IF($B12="","",COUNTIFS(REGISTRO!$B$2:$B$1722,$B12,REGISTRO!$H$2:$H$1722,$C$5,REGISTRO!$J$2:$J$1722,"FESTIVO")) | K12: =IF($B12="","",COUNTIFS(REGISTRO!$B$2:$B$1722,$B12,REGISTRO!$H$2:$H$1722,$C$5,REGISTRO!$J$2:$J$1722,"INCAPACIDAD")) | L12: =IF($B12="","",COUNTIFS(REGISTRO!$B$2:$B$1722,$B12,REGISTRO!$H$2:$H$1722,$C$5,REGISTRO!$J$2:$J$1722,"PERMISO")) | M12: =IF($B12="","",COUNTIFS(REGISTRO!$B$2:$B$1722,$B12,REGISTRO!$H$2:$H$1722,$C$5,REGISTRO!$J$2:$J$1722,"DESCANSO")) | N12: =IF($B12="","",COUNTIFS(REGISTRO!$B$2:$B$1722,$B12,REGISTRO!$H$2:$H$1722,$C$5,REGISTRO!$J$2:$J$1722,"DESCANSO POR DINAMICA")) | O12: =IF($B12="","",COUNTIFS(REGISTRO!$B$2:$B$1722,$B12,REGISTRO!$H$2:$H$1722,$C$5,REGISTRO!$J$2:$J$1722,"DINAMICA"))
B13: {=IFERROR(INDEX(PERSONAL!$A:$A,MATCH($B$3&"|"&6,PERSONAL!$N:$N,0)),"")} | C13: {=IFERROR(INDEX(PERSONAL!$B:$B,MATCH($B$3&"|"&6,PERSONAL!$N:$N,0)),"")} | D13: =IF($B13="","",COUNTIFS(REGISTRO!$B$2:$B$1722,$B13,REGISTRO!$H$2:$H$1722,$C$5,REGISTRO!$J$2:$J$1722,"VERDE")) | E13: =IF($B13="","",COUNTIFS(REGISTRO!$B$2:$B$1722,$B13,REGISTRO!$H$2:$H$1722,$C$5,REGISTRO!$J$2:$J$1722,"AMARILLO")) | F13: =IF($B13="","",COUNTIFS(REGISTRO!$B$2:$B$1722,$B13,REGISTRO!$H$2:$H$1722,$C$5,REGISTRO!$J$2:$J$1722,"ROJO")) | G13: =IF($B13="","",COUNTIFS(REGISTRO!$B$2:$B$1722,$B13,REGISTRO!$H$2:$H$1722,$C$5,REGISTRO!$J$2:$J$1722,"ROJO FUERTE")) | H13: =IF($B13="","",COUNTIFS(REGISTRO!$B$2:$B$1722,$B13,REGISTRO!$H$2:$H$1722,$C$5,REGISTRO!$J$2:$J$1722,"FALTA")) | I13: =IF($B13="","",COUNTIFS(REGISTRO!$B$2:$B$1722,$B13,REGISTRO!$H$2:$H$1722,$C$5,REGISTRO!$J$2:$J$1722,"VACACIONES")) | J13: =IF($B13="","",COUNTIFS(REGISTRO!$B$2:$B$1722,$B13,REGISTRO!$H$2:$H$1722,$C$5,REGISTRO!$J$2:$J$1722,"FESTIVO")) | K13: =IF($B13="","",COUNTIFS(REGISTRO!$B$2:$B$1722,$B13,REGISTRO!$H$2:$H$1722,$C$5,REGISTRO!$J$2:$J$1722,"INCAPACIDAD")) | L13: =IF($B13="","",COUNTIFS(REGISTRO!$B$2:$B$1722,$B13,REGISTRO!$H$2:$H$1722,$C$5,REGISTRO!$J$2:$J$1722,"PERMISO")) | M13: =IF($B13="","",COUNTIFS(REGISTRO!$B$2:$B$1722,$B13,REGISTRO!$H$2:$H$1722,$C$5,REGISTRO!$J$2:$J$1722,"DESCANSO")) | N13: =IF($B13="","",COUNTIFS(REGISTRO!$B$2:$B$1722,$B13,REGISTRO!$H$2:$H$1722,$C$5,REGISTRO!$J$2:$J$1722,"DESCANSO POR DINAMICA")) | O13: =IF($B13="","",COUNTIFS(REGISTRO!$B$2:$B$1722,$B13,REGISTRO!$H$2:$H$1722,$C$5,REGISTRO!$J$2:$J$1722,"DINAMICA"))
B14: {=IFERROR(INDEX(PERSONAL!$A:$A,MATCH($B$3&"|"&7,PERSONAL!$N:$N,0)),"")} | C14: {=IFERROR(INDEX(PERSONAL!$B:$B,MATCH($B$3&"|"&7,PERSONAL!$N:$N,0)),"")} | D14: =IF($B14="","",COUNTIFS(REGISTRO!$B$2:$B$1722,$B14,REGISTRO!$H$2:$H$1722,$C$5,REGISTRO!$J$2:$J$1722,"VERDE")) | E14: =IF($B14="","",COUNTIFS(REGISTRO!$B$2:$B$1722,$B14,REGISTRO!$H$2:$H$1722,$C$5,REGISTRO!$J$2:$J$1722,"AMARILLO")) | F14: =IF($B14="","",COUNTIFS(REGISTRO!$B$2:$B$1722,$B14,REGISTRO!$H$2:$H$1722,$C$5,REGISTRO!$J$2:$J$1722,"ROJO")) | G14: =IF($B14="","",COUNTIFS(REGISTRO!$B$2:$B$1722,$B14,REGISTRO!$H$2:$H$1722,$C$5,REGISTRO!$J$2:$J$1722,"ROJO FUERTE")) | H14: =IF($B14="","",COUNTIFS(REGISTRO!$B$2:$B$1722,$B14,REGISTRO!$H$2:$H$1722,$C$5,REGISTRO!$J$2:$J$1722,"FALTA")) | I14: =IF($B14="","",COUNTIFS(REGISTRO!$B$2:$B$1722,$B14,REGISTRO!$H$2:$H$1722,$C$5,REGISTRO!$J$2:$J$1722,"VACACIONES")) | J14: =IF($B14="","",COUNTIFS(REGISTRO!$B$2:$B$1722,$B14,REGISTRO!$H$2:$H$1722,$C$5,REGISTRO!$J$2:$J$1722,"FESTIVO")) | K14: =IF($B14="","",COUNTIFS(REGISTRO!$B$2:$B$1722,$B14,REGISTRO!$H$2:$H$1722,$C$5,REGISTRO!$J$2:$J$1722,"INCAPACIDAD")) | L14: =IF($B14="","",COUNTIFS(REGISTRO!$B$2:$B$1722,$B14,REGISTRO!$H$2:$H$1722,$C$5,REGISTRO!$J$2:$J$1722,"PERMISO")) | M14: =IF($B14="","",COUNTIFS(REGISTRO!$B$2:$B$1722,$B14,REGISTRO!$H$2:$H$1722,$C$5,REGISTRO!$J$2:$J$1722,"DESCANSO")) | N14: =IF($B14="","",COUNTIFS(REGISTRO!$B$2:$B$1722,$B14,REGISTRO!$H$2:$H$1722,$C$5,REGISTRO!$J$2:$J$1722,"DESCANSO POR DINAMICA")) | O14: =IF($B14="","",COUNTIFS(REGISTRO!$B$2:$B$1722,$B14,REGISTRO!$H$2:$H$1722,$C$5,REGISTRO!$J$2:$J$1722,"DINAMICA"))
B15: {=IFERROR(INDEX(PERSONAL!$A:$A,MATCH($B$3&"|"&8,PERSONAL!$N:$N,0)),"")} | C15: {=IFERROR(INDEX(PERSONAL!$B:$B,MATCH($B$3&"|"&8,PERSONAL!$N:$N,0)),"")} | D15: =IF($B15="","",COUNTIFS(REGISTRO!$B$2:$B$1722,$B15,REGISTRO!$H$2:$H$1722,$C$5,REGISTRO!$J$2:$J$1722,"VERDE")) | E15: =IF($B15="","",COUNTIFS(REGISTRO!$B$2:$B$1722,$B15,REGISTRO!$H$2:$H$1722,$C$5,REGISTRO!$J$2:$J$1722,"AMARILLO")) | F15: =IF($B15="","",COUNTIFS(REGISTRO!$B$2:$B$1722,$B15,REGISTRO!$H$2:$H$1722,$C$5,REGISTRO!$J$2:$J$1722,"ROJO")) | G15: =IF($B15="","",COUNTIFS(REGISTRO!$B$2:$B$1722,$B15,REGISTRO!$H$2:$H$1722,$C$5,REGISTRO!$J$2:$J$1722,"ROJO FUERTE")) | H15: =IF($B15="","",COUNTIFS(REGISTRO!$B$2:$B$1722,$B15,REGISTRO!$H$2:$H$1722,$C$5,REGISTRO!$J$2:$J$1722,"FALTA")) | I15: =IF($B15="","",COUNTIFS(REGISTRO!$B$2:$B$1722,$B15,REGISTRO!$H$2:$H$1722,$C$5,REGISTRO!$J$2:$J$1722,"VACACIONES")) | J15: =IF($B15="","",COUNTIFS(REGISTRO!$B$2:$B$1722,$B15,REGISTRO!$H$2:$H$1722,$C$5,REGISTRO!$J$2:$J$1722,"FESTIVO")) | K15: =IF($B15="","",COUNTIFS(REGISTRO!$B$2:$B$1722,$B15,REGISTRO!$H$2:$H$1722,$C$5,REGISTRO!$J$2:$J$1722,"INCAPACIDAD")) | L15: =IF($B15="","",COUNTIFS(REGISTRO!$B$2:$B$1722,$B15,REGISTRO!$H$2:$H$1722,$C$5,REGISTRO!$J$2:$J$1722,"PERMISO")) | M15: =IF($B15="","",COUNTIFS(REGISTRO!$B$2:$B$1722,$B15,REGISTRO!$H$2:$H$1722,$C$5,REGISTRO!$J$2:$J$1722,"DESCANSO")) | N15: =IF($B15="","",COUNTIFS(REGISTRO!$B$2:$B$1722,$B15,REGISTRO!$H$2:$H$1722,$C$5,REGISTRO!$J$2:$J$1722,"DESCANSO POR DINAMICA")) | O15: =IF($B15="","",COUNTIFS(REGISTRO!$B$2:$B$1722,$B15,REGISTRO!$H$2:$H$1722,$C$5,REGISTRO!$J$2:$J$1722,"DINAMICA"))
B16: {=IFERROR(INDEX(PERSONAL!$A:$A,MATCH($B$3&"|"&9,PERSONAL!$N:$N,0)),"")} | C16: {=IFERROR(INDEX(PERSONAL!$B:$B,MATCH($B$3&"|"&9,PERSONAL!$N:$N,0)),"")} | D16: =IF($B16="","",COUNTIFS(REGISTRO!$B$2:$B$1722,$B16,REGISTRO!$H$2:$H$1722,$C$5,REGISTRO!$J$2:$J$1722,"VERDE")) | E16: =IF($B16="","",COUNTIFS(REGISTRO!$B$2:$B$1722,$B16,REGISTRO!$H$2:$H$1722,$C$5,REGISTRO!$J$2:$J$1722,"AMARILLO")) | F16: =IF($B16="","",COUNTIFS(REGISTRO!$B$2:$B$1722,$B16,REGISTRO!$H$2:$H$1722,$C$5,REGISTRO!$J$2:$J$1722,"ROJO")) | G16: =IF($B16="","",COUNTIFS(REGISTRO!$B$2:$B$1722,$B16,REGISTRO!$H$2:$H$1722,$C$5,REGISTRO!$J$2:$J$1722,"ROJO FUERTE")) | H16: =IF($B16="","",COUNTIFS(REGISTRO!$B$2:$B$1722,$B16,REGISTRO!$H$2:$H$1722,$C$5,REGISTRO!$J$2:$J$1722,"FALTA")) | I16: =IF($B16="","",COUNTIFS(REGISTRO!$B$2:$B$1722,$B16,REGISTRO!$H$2:$H$1722,$C$5,REGISTRO!$J$2:$J$1722,"VACACIONES")) | J16: =IF($B16="","",COUNTIFS(REGISTRO!$B$2:$B$1722,$B16,REGISTRO!$H$2:$H$1722,$C$5,REGISTRO!$J$2:$J$1722,"FESTIVO")) | K16: =IF($B16="","",COUNTIFS(REGISTRO!$B$2:$B$1722,$B16,REGISTRO!$H$2:$H$1722,$C$5,REGISTRO!$J$2:$J$1722,"INCAPACIDAD")) | L16: =IF($B16="","",COUNTIFS(REGISTRO!$B$2:$B$1722,$B16,REGISTRO!$H$2:$H$1722,$C$5,REGISTRO!$J$2:$J$1722,"PERMISO")) | M16: =IF($B16="","",COUNTIFS(REGISTRO!$B$2:$B$1722,$B16,REGISTRO!$H$2:$H$1722,$C$5,REGISTRO!$J$2:$J$1722,"DESCANSO")) | N16: =IF($B16="","",COUNTIFS(REGISTRO!$B$2:$B$1722,$B16,REGISTRO!$H$2:$H$1722,$C$5,REGISTRO!$J$2:$J$1722,"DESCANSO POR DINAMICA")) | O16: =IF($B16="","",COUNTIFS(REGISTRO!$B$2:$B$1722,$B16,REGISTRO!$H$2:$H$1722,$C$5,REGISTRO!$J$2:$J$1722,"DINAMICA"))
B17: {=IFERROR(INDEX(PERSONAL!$A:$A,MATCH($B$3&"|"&10,PERSONAL!$N:$N,0)),"")} | C17: {=IFERROR(INDEX(PERSONAL!$B:$B,MATCH($B$3&"|"&10,PERSONAL!$N:$N,0)),"")} | D17: =IF($B17="","",COUNTIFS(REGISTRO!$B$2:$B$1722,$B17,REGISTRO!$H$2:$H$1722,$C$5,REGISTRO!$J$2:$J$1722,"VERDE")) | E17: =IF($B17="","",COUNTIFS(REGISTRO!$B$2:$B$1722,$B17,REGISTRO!$H$2:$H$1722,$C$5,REGISTRO!$J$2:$J$1722,"AMARILLO")) | F17: =IF($B17="","",COUNTIFS(REGISTRO!$B$2:$B$1722,$B17,REGISTRO!$H$2:$H$1722,$C$5,REGISTRO!$J$2:$J$1722,"ROJO")) | G17: =IF($B17="","",COUNTIFS(REGISTRO!$B$2:$B$1722,$B17,REGISTRO!$H$2:$H$1722,$C$5,REGISTRO!$J$2:$J$1722,"ROJO FUERTE")) | H17: =IF($B17="","",COUNTIFS(REGISTRO!$B$2:$B$1722,$B17,REGISTRO!$H$2:$H$1722,$C$5,REGISTRO!$J$2:$J$1722,"FALTA")) | I17: =IF($B17="","",COUNTIFS(REGISTRO!$B$2:$B$1722,$B17,REGISTRO!$H$2:$H$1722,$C$5,REGISTRO!$J$2:$J$1722,"VACACIONES")) | J17: =IF($B17="","",COUNTIFS(REGISTRO!$B$2:$B$1722,$B17,REGISTRO!$H$2:$H$1722,$C$5,REGISTRO!$J$2:$J$1722,"FESTIVO")) | K17: =IF($B17="","",COUNTIFS(REGISTRO!$B$2:$B$1722,$B17,REGISTRO!$H$2:$H$1722,$C$5,REGISTRO!$J$2:$J$1722,"INCAPACIDAD")) | L17: =IF($B17="","",COUNTIFS(REGISTRO!$B$2:$B$1722,$B17,REGISTRO!$H$2:$H$1722,$C$5,REGISTRO!$J$2:$J$1722,"PERMISO")) | M17: =IF($B17="","",COUNTIFS(REGISTRO!$B$2:$B$1722,$B17,REGISTRO!$H$2:$H$1722,$C$5,REGISTRO!$J$2:$J$1722,"DESCANSO")) | N17: =IF($B17="","",COUNTIFS(REGISTRO!$B$2:$B$1722,$B17,REGISTRO!$H$2:$H$1722,$C$5,REGISTRO!$J$2:$J$1722,"DESCANSO POR DINAMICA")) | O17: =IF($B17="","",COUNTIFS(REGISTRO!$B$2:$B$1722,$B17,REGISTRO!$H$2:$H$1722,$C$5,REGISTRO!$J$2:$J$1722,"DINAMICA"))
B18: {=IFERROR(INDEX(PERSONAL!$A:$A,MATCH($B$3&"|"&11,PERSONAL!$N:$N,0)),"")} | C18: {=IFERROR(INDEX(PERSONAL!$B:$B,MATCH($B$3&"|"&11,PERSONAL!$N:$N,0)),"")} | D18: =IF($B18="","",COUNTIFS(REGISTRO!$B$2:$B$1722,$B18,REGISTRO!$H$2:$H$1722,$C$5,REGISTRO!$J$2:$J$1722,"VERDE")) | E18: =IF($B18="","",COUNTIFS(REGISTRO!$B$2:$B$1722,$B18,REGISTRO!$H$2:$H$1722,$C$5,REGISTRO!$J$2:$J$1722,"AMARILLO")) | F18: =IF($B18="","",COUNTIFS(REGISTRO!$B$2:$B$1722,$B18,REGISTRO!$H$2:$H$1722,$C$5,REGISTRO!$J$2:$J$1722,"ROJO")) | G18: =IF($B18="","",COUNTIFS(REGISTRO!$B$2:$B$1722,$B18,REGISTRO!$H$2:$H$1722,$C$5,REGISTRO!$J$2:$J$1722,"ROJO FUERTE")) | H18: =IF($B18="","",COUNTIFS(REGISTRO!$B$2:$B$1722,$B18,REGISTRO!$H$2:$H$1722,$C$5,REGISTRO!$J$2:$J$1722,"FALTA")) | I18: =IF($B18="","",COUNTIFS(REGISTRO!$B$2:$B$1722,$B18,REGISTRO!$H$2:$H$1722,$C$5,REGISTRO!$J$2:$J$1722,"VACACIONES")) | J18: =IF($B18="","",COUNTIFS(REGISTRO!$B$2:$B$1722,$B18,REGISTRO!$H$2:$H$1722,$C$5,REGISTRO!$J$2:$J$1722,"FESTIVO")) | K18: =IF($B18="","",COUNTIFS(REGISTRO!$B$2:$B$1722,$B18,REGISTRO!$H$2:$H$1722,$C$5,REGISTRO!$J$2:$J$1722,"INCAPACIDAD")) | L18: =IF($B18="","",COUNTIFS(REGISTRO!$B$2:$B$1722,$B18,REGISTRO!$H$2:$H$1722,$C$5,REGISTRO!$J$2:$J$1722,"PERMISO")) | M18: =IF($B18="","",COUNTIFS(REGISTRO!$B$2:$B$1722,$B18,REGISTRO!$H$2:$H$1722,$C$5,REGISTRO!$J$2:$J$1722,"DESCANSO")) | N18: =IF($B18="","",COUNTIFS(REGISTRO!$B$2:$B$1722,$B18,REGISTRO!$H$2:$H$1722,$C$5,REGISTRO!$J$2:$J$1722,"DESCANSO POR DINAMICA")) | O18: =IF($B18="","",COUNTIFS(REGISTRO!$B$2:$B$1722,$B18,REGISTRO!$H$2:$H$1722,$C$5,REGISTRO!$J$2:$J$1722,"DINAMICA"))
B19: {=IFERROR(INDEX(PERSONAL!$A:$A,MATCH($B$3&"|"&12,PERSONAL!$N:$N,0)),"")} | C19: {=IFERROR(INDEX(PERSONAL!$B:$B,MATCH($B$3&"|"&12,PERSONAL!$N:$N,0)),"")} | D19: =IF($B19="","",COUNTIFS(REGISTRO!$B$2:$B$1722,$B19,REGISTRO!$H$2:$H$1722,$C$5,REGISTRO!$J$2:$J$1722,"VERDE")) | E19: =IF($B19="","",COUNTIFS(REGISTRO!$B$2:$B$1722,$B19,REGISTRO!$H$2:$H$1722,$C$5,REGISTRO!$J$2:$J$1722,"AMARILLO")) | F19: =IF($B19="","",COUNTIFS(REGISTRO!$B$2:$B$1722,$B19,REGISTRO!$H$2:$H$1722,$C$5,REGISTRO!$J$2:$J$1722,"ROJO")) | G19: =IF($B19="","",COUNTIFS(REGISTRO!$B$2:$B$1722,$B19,REGISTRO!$H$2:$H$1722,$C$5,REGISTRO!$J$2:$J$1722,"ROJO FUERTE")) | H19: =IF($B19="","",COUNTIFS(REGISTRO!$B$2:$B$1722,$B19,REGISTRO!$H$2:$H$1722,$C$5,REGISTRO!$J$2:$J$1722,"FALTA")) | I19: =IF($B19="","",COUNTIFS(REGISTRO!$B$2:$B$1722,$B19,REGISTRO!$H$2:$H$1722,$C$5,REGISTRO!$J$2:$J$1722,"VACACIONES")) | J19: =IF($B19="","",COUNTIFS(REGISTRO!$B$2:$B$1722,$B19,REGISTRO!$H$2:$H$1722,$C$5,REGISTRO!$J$2:$J$1722,"FESTIVO")) | K19: =IF($B19="","",COUNTIFS(REGISTRO!$B$2:$B$1722,$B19,REGISTRO!$H$2:$H$1722,$C$5,REGISTRO!$J$2:$J$1722,"INCAPACIDAD")) | L19: =IF($B19="","",COUNTIFS(REGISTRO!$B$2:$B$1722,$B19,REGISTRO!$H$2:$H$1722,$C$5,REGISTRO!$J$2:$J$1722,"PERMISO")) | M19: =IF($B19="","",COUNTIFS(REGISTRO!$B$2:$B$1722,$B19,REGISTRO!$H$2:$H$1722,$C$5,REGISTRO!$J$2:$J$1722,"DESCANSO")) | N19: =IF($B19="","",COUNTIFS(REGISTRO!$B$2:$B$1722,$B19,REGISTRO!$H$2:$H$1722,$C$5,REGISTRO!$J$2:$J$1722,"DESCANSO POR DINAMICA")) | O19: =IF($B19="","",COUNTIFS(REGISTRO!$B$2:$B$1722,$B19,REGISTRO!$H$2:$H$1722,$C$5,REGISTRO!$J$2:$J$1722,"DINAMICA"))
B20: TOTAL | D20: =SUM(D8:D19) | E20: =SUM(E8:E19) | F20: =SUM(F8:F19) | G20: =SUM(G8:G19) | H20: =SUM(H8:H19) | I20: =SUM(I8:I19) | J20: =SUM(J8:J19) | K20: =SUM(K8:K19) | ... O20: =SUM(O8:O19)
B21: % VERDE | D21: =IF(SUM(D20:H20)=0,0,D20/SUM(D20:H20))
B22: REGISTROS / PROM. HORAS | D22: =COUNTIFS(REGISTRO!$F$2:$F$1722,$B$3,REGISTRO!$H$2:$H$1722,$C$5) | E22: =IFERROR(AVERAGEIFS(REGISTRO!$K$2:$K$1722,REGISTRO!$F$2:$F$1722,$B$3,REGISTRO!$H$2:$H$1722,$C$5),0)
A1000: Demo publico: datos ficticios anonimizados para portafolio.

Sheet MATEO HERRERA SOLIS
B2: SUPERVISOR
B3: MATEO HERRERA SOLIS
B5: PERIODO | C5: JUNIO | D5: AÑO 2026
B6: ASESORES
B7: No. EMP | C7: NOMBRE | D7: VERDE | E7: AMARILLO | F7: ROJO | G7: ROJO FUERTE | H7: FALTA | I7: VACACIONES | J7: FESTIVO | K7: INCAPACIDAD | L7: PERMISO | M7: DESCANSO | N7: DESCANSO POR DINAMICA | O7: DINAMICA
B8: {=IFERROR(INDEX(PERSONAL!$A:$A,MATCH($B$3&"|"&1,PERSONAL!$N:$N,0)),"")} | C8: {=IFERROR(INDEX(PERSONAL!$B:$B,MATCH($B$3&"|"&1,PERSONAL!$N:$N,0)),"")} | D8: =IF($B8="","",COUNTIFS(REGISTRO!$B$2:$B$1722,$B8,REGISTRO!$H$2:$H$1722,$C$5,REGISTRO!$J$2:$J$1722,"VERDE")) | E8: =IF($B8="","",COUNTIFS(REGISTRO!$B$2:$B$1722,$B8,REGISTRO!$H$2:$H$1722,$C$5,REGISTRO!$J$2:$J$1722,"AMARILLO")) | F8: =IF($B8="","",COUNTIFS(REGISTRO!$B$2:$B$1722,$B8,REGISTRO!$H$2:$H$1722,$C$5,REGISTRO!$J$2:$J$1722,"ROJO")) | G8: =IF($B8="","",COUNTIFS(REGISTRO!$B$2:$B$1722,$B8,REGISTRO!$H$2:$H$1722,$C$5,REGISTRO!$J$2:$J$1722,"ROJO FUERTE")) | H8: =IF($B8="","",COUNTIFS(REGISTRO!$B$2:$B$1722,$B8,REGISTRO!$H$2:$H$1722,$C$5,REGISTRO!$J$2:$J$1722,"FALTA")) | I8: =IF($B8="","",COUNTIFS(REGISTRO!$B$2:$B$1722,$B8,REGISTRO!$H$2:$H$1722,$C$5,REGISTRO!$J$2:$J$1722,"VACACIONES")) | J8: =IF($B8="","",COUNTIFS(REGISTRO!$B$2:$B$1722,$B8,REGISTRO!$H$2:$H$1722,$C$5,REGISTRO!$J$2:$J$1722,"FESTIVO")) | K8: =IF($B8="","",COUNTIFS(REGISTRO!$B$2:$B$1722,$B8,REGISTRO!$H$2:$H$1722,$C$5,REGISTRO!$J$2:$J$1722,"INCAPACIDAD")) | L8: =IF($B8="","",COUNTIFS(REGISTRO!$B$2:$B$1722,$B8,REGISTRO!$H$2:$H$1722,$C$5,REGISTRO!$J$2:$J$1722,"PERMISO")) | M8: =IF($B8="","",COUNTIFS(REGISTRO!$B$2:$B$1722,$B8,REGISTRO!$H$2:$H$1722,$C$5,REGISTRO!$J$2:$J$1722,"DESCANSO")) | N8: =IF($B8="","",COUNTIFS(REGISTRO!$B$2:$B$1722,$B8,REGISTRO!$H$2:$H$1722,$C$5,REGISTRO!$J$2:$J$1722,"DESCANSO POR DINAMICA")) | O8: =IF($B8="","",COUNTIFS(REGISTRO!$B$2:$B$1722,$B8,REGISTRO!$H$2:$H$1722,$C$5,REGISTRO!$J$2:$J$1722,"DINAMICA"))
B9: {=IFERROR(INDEX(PERSONAL!$A:$A,MATCH($B$3&"|"&2,PERSONAL!$N:$N,0)),"")} | C9: {=IFERROR(INDEX(PERSONAL!$B:$B,MATCH($B$3&"|"&2,PERSONAL!$N:$N,0)),"")} | D9: =IF($B9="","",COUNTIFS(REGISTRO!$B$2:$B$1722,$B9,REGISTRO!$H$2:$H$1722,$C$5,REGISTRO!$J$2:$J$1722,"VERDE")) | E9: =IF($B9="","",COUNTIFS(REGISTRO!$B$2:$B$1722,$B9,REGISTRO!$H$2:$H$1722,$C$5,REGISTRO!$J$2:$J$1722,"AMARILLO")) | F9: =IF($B9="","",COUNTIFS(REGISTRO!$B$2:$B$1722,$B9,REGISTRO!$H$2:$H$1722,$C$5,REGISTRO!$J$2:$J$1722,"ROJO")) | G9: =IF($B9="","",COUNTIFS(REGISTRO!$B$2:$B$1722,$B9,REGISTRO!$H$2:$H$1722,$C$5,REGISTRO!$J$2:$J$1722,"ROJO FUERTE")) | H9: =IF($B9="","",COUNTIFS(REGISTRO!$B$2:$B$1722,$B9,REGISTRO!$H$2:$H$1722,$C$5,REGISTRO!$J$2:$J$1722,"FALTA")) | I9: =IF($B9="","",COUNTIFS(REGISTRO!$B$2:$B$1722,$B9,REGISTRO!$H$2:$H$1722,$C$5,REGISTRO!$J$2:$J$1722,"VACACIONES")) | J9: =IF($B9="","",COUNTIFS(REGISTRO!$B$2:$B$1722,$B9,REGISTRO!$H$2:$H$1722,$C$5,REGISTRO!$J$2:$J$1722,"FESTIVO")) | K9: =IF($B9="","",COUNTIFS(REGISTRO!$B$2:$B$1722,$B9,REGISTRO!$H$2:$H$1722,$C$5,REGISTRO!$J$2:$J$1722,"INCAPACIDAD")) | L9: =IF($B9="","",COUNTIFS(REGISTRO!$B$2:$B$1722,$B9,REGISTRO!$H$2:$H$1722,$C$5,REGISTRO!$J$2:$J$1722,"PERMISO")) | M9: =IF($B9="","",COUNTIFS(REGISTRO!$B$2:$B$1722,$B9,REGISTRO!$H$2:$H$1722,$C$5,REGISTRO!$J$2:$J$1722,"DESCANSO")) | N9: =IF($B9="","",COUNTIFS(REGISTRO!$B$2:$B$1722,$B9,REGISTRO!$H$2:$H$1722,$C$5,REGISTRO!$J$2:$J$1722,"DESCANSO POR DINAMICA")) | O9: =IF($B9="","",COUNTIFS(REGISTRO!$B$2:$B$1722,$B9,REGISTRO!$H$2:$H$1722,$C$5,REGISTRO!$J$2:$J$1722,"DINAMICA"))
B10: {=IFERROR(INDEX(PERSONAL!$A:$A,MATCH($B$3&"|"&3,PERSONAL!$N:$N,0)),"")} | C10: {=IFERROR(INDEX(PERSONAL!$B:$B,MATCH($B$3&"|"&3,PERSONAL!$N:$N,0)),"")} | D10: =IF($B10="","",COUNTIFS(REGISTRO!$B$2:$B$1722,$B10,REGISTRO!$H$2:$H$1722,$C$5,REGISTRO!$J$2:$J$1722,"VERDE")) | E10: =IF($B10="","",COUNTIFS(REGISTRO!$B$2:$B$1722,$B10,REGISTRO!$H$2:$H$1722,$C$5,REGISTRO!$J$2:$J$1722,"AMARILLO")) | F10: =IF($B10="","",COUNTIFS(REGISTRO!$B$2:$B$1722,$B10,REGISTRO!$H$2:$H$1722,$C$5,REGISTRO!$J$2:$J$1722,"ROJO")) | G10: =IF($B10="","",COUNTIFS(REGISTRO!$B$2:$B$1722,$B10,REGISTRO!$H$2:$H$1722,$C$5,REGISTRO!$J$2:$J$1722,"ROJO FUERTE")) | H10: =IF($B10="","",COUNTIFS(REGISTRO!$B$2:$B$1722,$B10,REGISTRO!$H$2:$H$1722,$C$5,REGISTRO!$J$2:$J$1722,"FALTA")) | I10: =IF($B10="","",COUNTIFS(REGISTRO!$B$2:$B$1722,$B10,REGISTRO!$H$2:$H$1722,$C$5,REGISTRO!$J$2:$J$1722,"VACACIONES")) | J10: =IF($B10="","",COUNTIFS(REGISTRO!$B$2:$B$1722,$B10,REGISTRO!$H$2:$H$1722,$C$5,REGISTRO!$J$2:$J$1722,"FESTIVO")) | K10: =IF($B10="","",COUNTIFS(REGISTRO!$B$2:$B$1722,$B10,REGISTRO!$H$2:$H$1722,$C$5,REGISTRO!$J$2:$J$1722,"INCAPACIDAD")) | L10: =IF($B10="","",COUNTIFS(REGISTRO!$B$2:$B$1722,$B10,REGISTRO!$H$2:$H$1722,$C$5,REGISTRO!$J$2:$J$1722,"PERMISO")) | M10: =IF($B10="","",COUNTIFS(REGISTRO!$B$2:$B$1722,$B10,REGISTRO!$H$2:$H$1722,$C$5,REGISTRO!$J$2:$J$1722,"DESCANSO")) | N10: =IF($B10="","",COUNTIFS(REGISTRO!$B$2:$B$1722,$B10,REGISTRO!$H$2:$H$1722,$C$5,REGISTRO!$J$2:$J$1722,"DESCANSO POR DINAMICA")) | O10: =IF($B10="","",COUNTIFS(REGISTRO!$B$2:$B$1722,$B10,REGISTRO!$H$2:$H$1722,$C$5,REGISTRO!$J$2:$J$1722,"DINAMICA"))
B11: {=IFERROR(INDEX(PERSONAL!$A:$A,MATCH($B$3&"|"&4,PERSONAL!$N:$N,0)),"")} | C11: {=IFERROR(INDEX(PERSONAL!$B:$B,MATCH($B$3&"|"&4,PERSONAL!$N:$N,0)),"")} | D11: =IF($B11="","",COUNTIFS(REGISTRO!$B$2:$B$1722,$B11,REGISTRO!$H$2:$H$1722,$C$5,REGISTRO!$J$2:$J$1722,"VERDE")) | E11: =IF($B11="","",COUNTIFS(REGISTRO!$B$2:$B$1722,$B11,REGISTRO!$H$2:$H$1722,$C$5,REGISTRO!$J$2:$J$1722,"AMARILLO")) | F11: =IF($B11="","",COUNTIFS(REGISTRO!$B$2:$B$1722,$B11,REGISTRO!$H$2:$H$1722,$C$5,REGISTRO!$J$2:$J$1722,"ROJO")) | G11: =IF($B11="","",COUNTIFS(REGISTRO!$B$2:$B$1722,$B11,REGISTRO!$H$2:$H$1722,$C$5,REGISTRO!$J$2:$J$1722,"ROJO FUERTE")) | H11: =IF($B11="","",COUNTIFS(REGISTRO!$B$2:$B$1722,$B11,REGISTRO!$H$2:$H$1722,$C$5,REGISTRO!$J$2:$J$1722,"FALTA")) | I11: =IF($B11="","",COUNTIFS(REGISTRO!$B$2:$B$1722,$B11,REGISTRO!$H$2:$H$1722,$C$5,REGISTRO!$J$2:$J$1722,"VACACIONES")) | J11: =IF($B11="","",COUNTIFS(REGISTRO!$B$2:$B$1722,$B11,REGISTRO!$H$2:$H$1722,$C$5,REGISTRO!$J$2:$J$1722,"FESTIVO")) | K11: =IF($B11="","",COUNTIFS(REGISTRO!$B$2:$B$1722,$B11,REGISTRO!$H$2:$H$1722,$C$5,REGISTRO!$J$2:$J$1722,"INCAPACIDAD")) | L11: =IF($B11="","",COUNTIFS(REGISTRO!$B$2:$B$1722,$B11,REGISTRO!$H$2:$H$1722,$C$5,REGISTRO!$J$2:$J$1722,"PERMISO")) | M11: =IF($B11="","",COUNTIFS(REGISTRO!$B$2:$B$1722,$B11,REGISTRO!$H$2:$H$1722,$C$5,REGISTRO!$J$2:$J$1722,"DESCANSO")) | N11: =IF($B11="","",COUNTIFS(REGISTRO!$B$2:$B$1722,$B11,REGISTRO!$H$2:$H$1722,$C$5,REGISTRO!$J$2:$J$1722,"DESCANSO POR DINAMICA")) | O11: =IF($B11="","",COUNTIFS(REGISTRO!$B$2:$B$1722,$B11,REGISTRO!$H$2:$H$1722,$C$5,REGISTRO!$J$2:$J$1722,"DINAMICA"))
B12: {=IFERROR(INDEX(PERSONAL!$A:$A,MATCH($B$3&"|"&5,PERSONAL!$N:$N,0)),"")} | C12: {=IFERROR(INDEX(PERSONAL!$B:$B,MATCH($B$3&"|"&5,PERSONAL!$N:$N,0)),"")} | D12: =IF($B12="","",COUNTIFS(REGISTRO!$B$2:$B$1722,$B12,REGISTRO!$H$2:$H$1722,$C$5,REGISTRO!$J$2:$J$1722,"VERDE")) | E12: =IF($B12="","",COUNTIFS(REGISTRO!$B$2:$B$1722,$B12,REGISTRO!$H$2:$H$1722,$C$5,REGISTRO!$J$2:$J$1722,"AMARILLO")) | F12: =IF($B12="","",COUNTIFS(REGISTRO!$B$2:$B$1722,$B12,REGISTRO!$H$2:$H$1722,$C$5,REGISTRO!$J$2:$J$1722,"ROJO")) | G12: =IF($B12="","",COUNTIFS(REGISTRO!$B$2:$B$1722,$B12,REGISTRO!$H$2:$H$1722,$C$5,REGISTRO!$J$2:$J$1722,"ROJO FUERTE")) | H12: =IF($B12="","",COUNTIFS(REGISTRO!$B$2:$B$1722,$B12,REGISTRO!$H$2:$H$1722,$C$5,REGISTRO!$J$2:$J$1722,"FALTA")) | I12: =IF($B12="","",COUNTIFS(REGISTRO!$B$2:$B$1722,$B12,REGISTRO!$H$2:$H$1722,$C$5,REGISTRO!$J$2:$J$1722,"VACACIONES")) | J12: =IF($B12="","",COUNTIFS(REGISTRO!$B$2:$B$1722,$B12,REGISTRO!$H$2:$H$1722,$C$5,REGISTRO!$J$2:$J$1722,"FESTIVO")) | K12: =IF($B12="","",COUNTIFS(REGISTRO!$B$2:$B$1722,$B12,REGISTRO!$H$2:$H$1722,$C$5,REGISTRO!$J$2:$J$1722,"INCAPACIDAD")) | L12: =IF($B12="","",COUNTIFS(REGISTRO!$B$2:$B$1722,$B12,REGISTRO!$H$2:$H$1722,$C$5,REGISTRO!$J$2:$J$1722,"PERMISO")) | M12: =IF($B12="","",COUNTIFS(REGISTRO!$B$2:$B$1722,$B12,REGISTRO!$H$2:$H$1722,$C$5,REGISTRO!$J$2:$J$1722,"DESCANSO")) | N12: =IF($B12="","",COUNTIFS(REGISTRO!$B$2:$B$1722,$B12,REGISTRO!$H$2:$H$1722,$C$5,REGISTRO!$J$2:$J$1722,"DESCANSO POR DINAMICA")) | O12: =IF($B12="","",COUNTIFS(REGISTRO!$B$2:$B$1722,$B12,REGISTRO!$H$2:$H$1722,$C$5,REGISTRO!$J$2:$J$1722,"DINAMICA"))
B13: {=IFERROR(INDEX(PERSONAL!$A:$A,MATCH($B$3&"|"&6,PERSONAL!$N:$N,0)),"")} | C13: {=IFERROR(INDEX(PERSONAL!$B:$B,MATCH($B$3&"|"&6,PERSONAL!$N:$N,0)),"")} | D13: =IF($B13="","",COUNTIFS(REGISTRO!$B$2:$B$1722,$B13,REGISTRO!$H$2:$H$1722,$C$5,REGISTRO!$J$2:$J$1722,"VERDE")) | E13: =IF($B13="","",COUNTIFS(REGISTRO!$B$2:$B$1722,$B13,REGISTRO!$H$2:$H$1722,$C$5,REGISTRO!$J$2:$J$1722,"AMARILLO")) | F13: =IF($B13="","",COUNTIFS(REGISTRO!$B$2:$B$1722,$B13,REGISTRO!$H$2:$H$1722,$C$5,REGISTRO!$J$2:$J$1722,"ROJO")) | G13: =IF($B13="","",COUNTIFS(REGISTRO!$B$2:$B$1722,$B13,REGISTRO!$H$2:$H$1722,$C$5,REGISTRO!$J$2:$J$1722,"ROJO FUERTE")) | H13: =IF($B13="","",COUNTIFS(REGISTRO!$B$2:$B$1722,$B13,REGISTRO!$H$2:$H$1722,$C$5,REGISTRO!$J$2:$J$1722,"FALTA")) | I13: =IF($B13="","",COUNTIFS(REGISTRO!$B$2:$B$1722,$B13,REGISTRO!$H$2:$H$1722,$C$5,REGISTRO!$J$2:$J$1722,"VACACIONES")) | J13: =IF($B13="","",COUNTIFS(REGISTRO!$B$2:$B$1722,$B13,REGISTRO!$H$2:$H$1722,$C$5,REGISTRO!$J$2:$J$1722,"FESTIVO")) | K13: =IF($B13="","",COUNTIFS(REGISTRO!$B$2:$B$1722,$B13,REGISTRO!$H$2:$H$1722,$C$5,REGISTRO!$J$2:$J$1722,"INCAPACIDAD")) | L13: =IF($B13="","",COUNTIFS(REGISTRO!$B$2:$B$1722,$B13,REGISTRO!$H$2:$H$1722,$C$5,REGISTRO!$J$2:$J$1722,"PERMISO")) | M13: =IF($B13="","",COUNTIFS(REGISTRO!$B$2:$B$1722,$B13,REGISTRO!$H$2:$H$1722,$C$5,REGISTRO!$J$2:$J$1722,"DESCANSO")) | N13: =IF($B13="","",COUNTIFS(REGISTRO!$B$2:$B$1722,$B13,REGISTRO!$H$2:$H$1722,$C$5,REGISTRO!$J$2:$J$1722,"DESCANSO POR DINAMICA")) | O13: =IF($B13="","",COUNTIFS(REGISTRO!$B$2:$B$1722,$B13,REGISTRO!$H$2:$H$1722,$C$5,REGISTRO!$J$2:$J$1722,"DINAMICA"))
B14: {=IFERROR(INDEX(PERSONAL!$A:$A,MATCH($B$3&"|"&7,PERSONAL!$N:$N,0)),"")} | C14: {=IFERROR(INDEX(PERSONAL!$B:$B,MATCH($B$3&"|"&7,PERSONAL!$N:$N,0)),"")} | D14: =IF($B14="","",COUNTIFS(REGISTRO!$B$2:$B$1722,$B14,REGISTRO!$H$2:$H$1722,$C$5,REGISTRO!$J$2:$J$1722,"VERDE")) | E14: =IF($B14="","",COUNTIFS(REGISTRO!$B$2:$B$1722,$B14,REGISTRO!$H$2:$H$1722,$C$5,REGISTRO!$J$2:$J$1722,"AMARILLO")) | F14: =IF($B14="","",COUNTIFS(REGISTRO!$B$2:$B$1722,$B14,REGISTRO!$H$2:$H$1722,$C$5,REGISTRO!$J$2:$J$1722,"ROJO")) | G14: =IF($B14="","",COUNTIFS(REGISTRO!$B$2:$B$1722,$B14,REGISTRO!$H$2:$H$1722,$C$5,REGISTRO!$J$2:$J$1722,"ROJO FUERTE")) | H14: =IF($B14="","",COUNTIFS(REGISTRO!$B$2:$B$1722,$B14,REGISTRO!$H$2:$H$1722,$C$5,REGISTRO!$J$2:$J$1722,"FALTA")) | I14: =IF($B14="","",COUNTIFS(REGISTRO!$B$2:$B$1722,$B14,REGISTRO!$H$2:$H$1722,$C$5,REGISTRO!$J$2:$J$1722,"VACACIONES")) | J14: =IF($B14="","",COUNTIFS(REGISTRO!$B$2:$B$1722,$B14,REGISTRO!$H$2:$H$1722,$C$5,REGISTRO!$J$2:$J$1722,"FESTIVO")) | K14: =IF($B14="","",COUNTIFS(REGISTRO!$B$2:$B$1722,$B14,REGISTRO!$H$2:$H$1722,$C$5,REGISTRO!$J$2:$J$1722,"INCAPACIDAD")) | L14: =IF($B14="","",COUNTIFS(REGISTRO!$B$2:$B$1722,$B14,REGISTRO!$H$2:$H$1722,$C$5,REGISTRO!$J$2:$J$1722,"PERMISO")) | M14: =IF($B14="","",COUNTIFS(REGISTRO!$B$2:$B$1722,$B14,REGISTRO!$H$2:$H$1722,$C$5,REGISTRO!$J$2:$J$1722,"DESCANSO")) | N14: =IF($B14="","",COUNTIFS(REGISTRO!$B$2:$B$1722,$B14,REGISTRO!$H$2:$H$1722,$C$5,REGISTRO!$J$2:$J$1722,"DESCANSO POR DINAMICA")) | O14: =IF($B14="","",COUNTIFS(REGISTRO!$B$2:$B$1722,$B14,REGISTRO!$H$2:$H$1722,$C$5,REGISTRO!$J$2:$J$1722,"DINAMICA"))
B15: {=IFERROR(INDEX(PERSONAL!$A:$A,MATCH($B$3&"|"&8,PERSONAL!$N:$N,0)),"")} | C15: {=IFERROR(INDEX(PERSONAL!$B:$B,MATCH($B$3&"|"&8,PERSONAL!$N:$N,0)),"")} | D15: =IF($B15="","",COUNTIFS(REGISTRO!$B$2:$B$1722,$B15,REGISTRO!$H$2:$H$1722,$C$5,REGISTRO!$J$2:$J$1722,"VERDE")) | E15: =IF($B15="","",COUNTIFS(REGISTRO!$B$2:$B$1722,$B15,REGISTRO!$H$2:$H$1722,$C$5,REGISTRO!$J$2:$J$1722,"AMARILLO")) | F15: =IF($B15="","",COUNTIFS(REGISTRO!$B$2:$B$1722,$B15,REGISTRO!$H$2:$H$1722,$C$5,REGISTRO!$J$2:$J$1722,"ROJO")) | G15: =IF($B15="","",COUNTIFS(REGISTRO!$B$2:$B$1722,$B15,REGISTRO!$H$2:$H$1722,$C$5,REGISTRO!$J$2:$J$1722,"ROJO FUERTE")) | H15: =IF($B15="","",COUNTIFS(REGISTRO!$B$2:$B$1722,$B15,REGISTRO!$H$2:$H$1722,$C$5,REGISTRO!$J$2:$J$1722,"FALTA")) | I15: =IF($B15="","",COUNTIFS(REGISTRO!$B$2:$B$1722,$B15,REGISTRO!$H$2:$H$1722,$C$5,REGISTRO!$J$2:$J$1722,"VACACIONES")) | J15: =IF($B15="","",COUNTIFS(REGISTRO!$B$2:$B$1722,$B15,REGISTRO!$H$2:$H$1722,$C$5,REGISTRO!$J$2:$J$1722,"FESTIVO")) | K15: =IF($B15="","",COUNTIFS(REGISTRO!$B$2:$B$1722,$B15,REGISTRO!$H$2:$H$1722,$C$5,REGISTRO!$J$2:$J$1722,"INCAPACIDAD")) | L15: =IF($B15="","",COUNTIFS(REGISTRO!$B$2:$B$1722,$B15,REGISTRO!$H$2:$H$1722,$C$5,REGISTRO!$J$2:$J$1722,"PERMISO")) | M15: =IF($B15="","",COUNTIFS(REGISTRO!$B$2:$B$1722,$B15,REGISTRO!$H$2:$H$1722,$C$5,REGISTRO!$J$2:$J$1722,"DESCANSO")) | N15: =IF($B15="","",COUNTIFS(REGISTRO!$B$2:$B$1722,$B15,REGISTRO!$H$2:$H$1722,$C$5,REGISTRO!$J$2:$J$1722,"DESCANSO POR DINAMICA")) | O15: =IF($B15="","",COUNTIFS(REGISTRO!$B$2:$B$1722,$B15,REGISTRO!$H$2:$H$1722,$C$5,REGISTRO!$J$2:$J$1722,"DINAMICA"))
B16: {=IFERROR(INDEX(PERSONAL!$A:$A,MATCH($B$3&"|"&9,PERSONAL!$N:$N,0)),"")} | C16: {=IFERROR(INDEX(PERSONAL!$B:$B,MATCH($B$3&"|"&9,PERSONAL!$N:$N,0)),"")} | D16: =IF($B16="","",COUNTIFS(REGISTRO!$B$2:$B$1722,$B16,REGISTRO!$H$2:$H$1722,$C$5,REGISTRO!$J$2:$J$1722,"VERDE")) | E16: =IF($B16="","",COUNTIFS(REGISTRO!$B$2:$B$1722,$B16,REGISTRO!$H$2:$H$1722,$C$5,REGISTRO!$J$2:$J$1722,"AMARILLO")) | F16: =IF($B16="","",COUNTIFS(REGISTRO!$B$2:$B$1722,$B16,REGISTRO!$H$2:$H$1722,$C$5,REGISTRO!$J$2:$J$1722,"ROJO")) | G16: =IF($B16="","",COUNTIFS(REGISTRO!$B$2:$B$1722,$B16,REGISTRO!$H$2:$H$1722,$C$5,REGISTRO!$J$2:$J$1722,"ROJO FUERTE")) | H16: =IF($B16="","",COUNTIFS(REGISTRO!$B$2:$B$1722,$B16,REGISTRO!$H$2:$H$1722,$C$5,REGISTRO!$J$2:$J$1722,"FALTA")) | I16: =IF($B16="","",COUNTIFS(REGISTRO!$B$2:$B$1722,$B16,REGISTRO!$H$2:$H$1722,$C$5,REGISTRO!$J$2:$J$1722,"VACACIONES")) | J16: =IF($B16="","",COUNTIFS(REGISTRO!$B$2:$B$1722,$B16,REGISTRO!$H$2:$H$1722,$C$5,REGISTRO!$J$2:$J$1722,"FESTIVO")) | K16: =IF($B16="","",COUNTIFS(REGISTRO!$B$2:$B$1722,$B16,REGISTRO!$H$2:$H$1722,$C$5,REGISTRO!$J$2:$J$1722,"INCAPACIDAD")) | L16: =IF($B16="","",COUNTIFS(REGISTRO!$B$2:$B$1722,$B16,REGISTRO!$H$2:$H$1722,$C$5,REGISTRO!$J$2:$J$1722,"PERMISO")) | M16: =IF($B16="","",COUNTIFS(REGISTRO!$B$2:$B$1722,$B16,REGISTRO!$H$2:$H$1722,$C$5,REGISTRO!$J$2:$J$1722,"DESCANSO")) | N16: =IF($B16="","",COUNTIFS(REGISTRO!$B$2:$B$1722,$B16,REGISTRO!$H$2:$H$1722,$C$5,REGISTRO!$J$2:$J$1722,"DESCANSO POR DINAMICA")) | O16: =IF($B16="","",COUNTIFS(REGISTRO!$B$2:$B$1722,$B16,REGISTRO!$H$2:$H$1722,$C$5,REGISTRO!$J$2:$J$1722,"DINAMICA"))
B17: {=IFERROR(INDEX(PERSONAL!$A:$A,MATCH($B$3&"|"&10,PERSONAL!$N:$N,0)),"")} | C17: {=IFERROR(INDEX(PERSONAL!$B:$B,MATCH($B$3&"|"&10,PERSONAL!$N:$N,0)),"")} | D17: =IF($B17="","",COUNTIFS(REGISTRO!$B$2:$B$1722,$B17,REGISTRO!$H$2:$H$1722,$C$5,REGISTRO!$J$2:$J$1722,"VERDE")) | E17: =IF($B17="","",COUNTIFS(REGISTRO!$B$2:$B$1722,$B17,REGISTRO!$H$2:$H$1722,$C$5,REGISTRO!$J$2:$J$1722,"AMARILLO")) | F17: =IF($B17="","",COUNTIFS(REGISTRO!$B$2:$B$1722,$B17,REGISTRO!$H$2:$H$1722,$C$5,REGISTRO!$J$2:$J$1722,"ROJO")) | G17: =IF($B17="","",COUNTIFS(REGISTRO!$B$2:$B$1722,$B17,REGISTRO!$H$2:$H$1722,$C$5,REGISTRO!$J$2:$J$1722,"ROJO FUERTE")) | H17: =IF($B17="","",COUNTIFS(REGISTRO!$B$2:$B$1722,$B17,REGISTRO!$H$2:$H$1722,$C$5,REGISTRO!$J$2:$J$1722,"FALTA")) | I17: =IF($B17="","",COUNTIFS(REGISTRO!$B$2:$B$1722,$B17,REGISTRO!$H$2:$H$1722,$C$5,REGISTRO!$J$2:$J$1722,"VACACIONES")) | J17: =IF($B17="","",COUNTIFS(REGISTRO!$B$2:$B$1722,$B17,REGISTRO!$H$2:$H$1722,$C$5,REGISTRO!$J$2:$J$1722,"FESTIVO")) | K17: =IF($B17="","",COUNTIFS(REGISTRO!$B$2:$B$1722,$B17,REGISTRO!$H$2:$H$1722,$C$5,REGISTRO!$J$2:$J$1722,"INCAPACIDAD")) | L17: =IF($B17="","",COUNTIFS(REGISTRO!$B$2:$B$1722,$B17,REGISTRO!$H$2:$H$1722,$C$5,REGISTRO!$J$2:$J$1722,"PERMISO")) | M17: =IF($B17="","",COUNTIFS(REGISTRO!$B$2:$B$1722,$B17,REGISTRO!$H$2:$H$1722,$C$5,REGISTRO!$J$2:$J$1722,"DESCANSO")) | N17: =IF($B17="","",COUNTIFS(REGISTRO!$B$2:$B$1722,$B17,REGISTRO!$H$2:$H$1722,$C$5,REGISTRO!$J$2:$J$1722,"DESCANSO POR DINAMICA")) | O17: =IF($B17="","",COUNTIFS(REGISTRO!$B$2:$B$1722,$B17,REGISTRO!$H$2:$H$1722,$C$5,REGISTRO!$J$2:$J$1722,"DINAMICA"))
B18: {=IFERROR(INDEX(PERSONAL!$A:$A,MATCH($B$3&"|"&11,PERSONAL!$N:$N,0)),"")} | C18: {=IFERROR(INDEX(PERSONAL!$B:$B,MATCH($B$3&"|"&11,PERSONAL!$N:$N,0)),"")} | D18: =IF($B18="","",COUNTIFS(REGISTRO!$B$2:$B$1722,$B18,REGISTRO!$H$2:$H$1722,$C$5,REGISTRO!$J$2:$J$1722,"VERDE")) | E18: =IF($B18="","",COUNTIFS(REGISTRO!$B$2:$B$1722,$B18,REGISTRO!$H$2:$H$1722,$C$5,REGISTRO!$J$2:$J$1722,"AMARILLO")) | F18: =IF($B18="","",COUNTIFS(REGISTRO!$B$2:$B$1722,$B18,REGISTRO!$H$2:$H$1722,$C$5,REGISTRO!$J$2:$J$1722,"ROJO")) | G18: =IF($B18="","",COUNTIFS(REGISTRO!$B$2:$B$1722,$B18,REGISTRO!$H$2:$H$1722,$C$5,REGISTRO!$J$2:$J$1722,"ROJO FUERTE")) | H18: =IF($B18="","",COUNTIFS(REGISTRO!$B$2:$B$1722,$B18,REGISTRO!$H$2:$H$1722,$C$5,REGISTRO!$J$2:$J$1722,"FALTA")) | I18: =IF($B18="","",COUNTIFS(REGISTRO!$B$2:$B$1722,$B18,REGISTRO!$H$2:$H$1722,$C$5,REGISTRO!$J$2:$J$1722,"VACACIONES")) | J18: =IF($B18="","",COUNTIFS(REGISTRO!$B$2:$B$1722,$B18,REGISTRO!$H$2:$H$1722,$C$5,REGISTRO!$J$2:$J$1722,"FESTIVO")) | K18: =IF($B18="","",COUNTIFS(REGISTRO!$B$2:$B$1722,$B18,REGISTRO!$H$2:$H$1722,$C$5,REGISTRO!$J$2:$J$1722,"INCAPACIDAD")) | L18: =IF($B18="","",COUNTIFS(REGISTRO!$B$2:$B$1722,$B18,REGISTRO!$H$2:$H$1722,$C$5,REGISTRO!$J$2:$J$1722,"PERMISO")) | M18: =IF($B18="","",COUNTIFS(REGISTRO!$B$2:$B$1722,$B18,REGISTRO!$H$2:$H$1722,$C$5,REGISTRO!$J$2:$J$1722,"DESCANSO")) | N18: =IF($B18="","",COUNTIFS(REGISTRO!$B$2:$B$1722,$B18,REGISTRO!$H$2:$H$1722,$C$5,REGISTRO!$J$2:$J$1722,"DESCANSO POR DINAMICA")) | O18: =IF($B18="","",COUNTIFS(REGISTRO!$B$2:$B$1722,$B18,REGISTRO!$H$2:$H$1722,$C$5,REGISTRO!$J$2:$J$1722,"DINAMICA"))
B19: {=IFERROR(INDEX(PERSONAL!$A:$A,MATCH($B$3&"|"&12,PERSONAL!$N:$N,0)),"")} | C19: {=IFERROR(INDEX(PERSONAL!$B:$B,MATCH($B$3&"|"&12,PERSONAL!$N:$N,0)),"")} | D19: =IF($B19="","",COUNTIFS(REGISTRO!$B$2:$B$1722,$B19,REGISTRO!$H$2:$H$1722,$C$5,REGISTRO!$J$2:$J$1722,"VERDE")) | E19: =IF($B19="","",COUNTIFS(REGISTRO!$B$2:$B$1722,$B19,REGISTRO!$H$2:$H$1722,$C$5,REGISTRO!$J$2:$J$1722,"AMARILLO")) | F19: =IF($B19="","",COUNTIFS(REGISTRO!$B$2:$B$1722,$B19,REGISTRO!$H$2:$H$1722,$C$5,REGISTRO!$J$2:$J$1722,"ROJO")) | G19: =IF($B19="","",COUNTIFS(REGISTRO!$B$2:$B$1722,$B19,REGISTRO!$H$2:$H$1722,$C$5,REGISTRO!$J$2:$J$1722,"ROJO FUERTE")) | H19: =IF($B19="","",COUNTIFS(REGISTRO!$B$2:$B$1722,$B19,REGISTRO!$H$2:$H$1722,$C$5,REGISTRO!$J$2:$J$1722,"FALTA")) | I19: =IF($B19="","",COUNTIFS(REGISTRO!$B$2:$B$1722,$B19,REGISTRO!$H$2:$H$1722,$C$5,REGISTRO!$J$2:$J$1722,"VACACIONES")) | J19: =IF($B19="","",COUNTIFS(REGISTRO!$B$2:$B$1722,$B19,REGISTRO!$H$2:$H$1722,$C$5,REGISTRO!$J$2:$J$1722,"FESTIVO")) | K19: =IF($B19="","",COUNTIFS(REGISTRO!$B$2:$B$1722,$B19,REGISTRO!$H$2:$H$1722,$C$5,REGISTRO!$J$2:$J$1722,"INCAPACIDAD")) | L19: =IF($B19="","",COUNTIFS(REGISTRO!$B$2:$B$1722,$B19,REGISTRO!$H$2:$H$1722,$C$5,REGISTRO!$J$2:$J$1722,"PERMISO")) | M19: =IF($B19="","",COUNTIFS(REGISTRO!$B$2:$B$1722,$B19,REGISTRO!$H$2:$H$1722,$C$5,REGISTRO!$J$2:$J$1722,"DESCANSO")) | N19: =IF($B19="","",COUNTIFS(REGISTRO!$B$2:$B$1722,$B19,REGISTRO!$H$2:$H$1722,$C$5,REGISTRO!$J$2:$J$1722,"DESCANSO POR DINAMICA")) | O19: =IF($B19="","",COUNTIFS(REGISTRO!$B$2:$B$1722,$B19,REGISTRO!$H$2:$H$1722,$C$5,REGISTRO!$J$2:$J$1722,"DINAMICA"))
B20: TOTAL | D20: =SUM(D8:D19) | E20: =SUM(E8:E19) | F20: =SUM(F8:F19) | G20: =SUM(G8:G19) | H20: =SUM(H8:H19) | I20: =SUM(I8:I19) | J20: =SUM(J8:J19) | K20: =SUM(K8:K19) | ... O20: =SUM(O8:O19)
B21: % VERDE | D21: =IF(SUM(D20:H20)=0,0,D20/SUM(D20:H20))
